Workbook
Name CIRCUITS: #REF!
Name CLASS: #REF!
Name DATES: #REF!
Name firstterm: #REF!
Name JokpeV5: REPORTCARD!$A$1:$M$1351
Name LEVEL400: #REF!
Name MONTHS: #REF!
Name REGIONS: #REF!
Name secondterm: #REF!
Name thirdterm: #REF!
Name XFD: SUMMARY!$S:$S

Sheet DATAENTRY
B2: jokpe School complex
C4: First Term
C5: Class: | D5: Basic 6
C6: CIRCUIT: | D6: Chereponi West | H6: North East | K6: :REGION
C7: COMMUNITY | D7: Ando-Nymanu | H7: Chereponi | K7: :DISTRICT
C8: MALE: | D8: =COUNTIF(D12:D56,"=M") -> 3 | E8: FEMALE: | F8: =COUNTIF(D12:D56,"=F") -> 3 | G8: TOTAL: | H8: =COUNTIF(D12:D56,"*") -> 6 | J8: Average Age: | K8: 15
C9: RESUMING DATE: | F9: TERM: | G9: =C4 -> First Term | H9: YEAR: | I9: =YEAR(TODAY()) -> 2026 | J9: VACATION DATE: | K9: 44275
B10: S/N | E10: ADMISSION DATA FOR LEARNERS AND THEIR GUADIANS | J10: Dev's Contact: +233241224773
C11: NAME OF STUDENT | D11: SEX | E11: INDEX NO. | F11: DATE OF BIRTH | G11: ADMISSION DATE | H11: COMPLITON DATE | I11: CERTIFICATE | J11: GUADIAN NAME | K11: CONTACT
B12: 1 | C12: KOFI AKPALU | D12: M | E12: 45847 | F12: 39695 | G12: 45638 | H12: 46154 | I12: BECE | J12: Baba Yabata | K12: 241224773
B13: 2 | C13: AMA JULIAM | D13: F | E13: 65759 | F13: 40017 | G13: 45639 | H13: 46154 | I13: BECE | J13: Numaba Bolalo | K13: 205742880
B14: 3 | C14: KOKU BONTO | D14: M | E14: 35378 | F14: 36447 | G14: 45640 | H14: 46154 | I14: BECE | J14: Gagaga Tanchi | K14: 262222800
B15: 4 | C15: DODOUKWE CHABA | D15: F | E15: 36379 | F15: 37384 | G15: 45641 | H15: 46155 | I15: BECE | J15: Elona Nanatub | K15: 533939393
B16: 5 | C16: AMINA FRIDAY | D16: M | E16: 220393 | F16: 36273 | G16: 42136 | H16: 46156 | I16: BECE | J16: GHANA AMA | K16: 241224773
B17: 6 | C17: BABA NINJA | D17: F | E17: 40404 | F17: 45070 | G17: 45739 | H17: 46157 | I17: BECE | J17: HUNU ANAN | K17: 262222800
B18: 7
B19: 8
B20: 9
B21: 10
B22: 11
B23: 12
B24: 13
B25: 14
B26: 15
B27: 16
B28: 17
B29: 18
... B56: 45

Sheet REGISTER
B2: TERM | E2: =DATAENTRY!B2 -> jokpe School complex | AC2: =DATAENTRY!B2 -> jokpe School complex | BA2: =DATAENTRY!B2 -> jokpe School complex | BY2: =DATAENTRY!B2 -> jokpe School complex | CW2: =DATAENTRY!G9 -> First Term
B3: =DATAENTRY!G9 -> First Term | CW3: BY FEKPE JOHN (+233241224773)
B4: COUNTRY: | C4: GHANA | E4: CIRCUIT : | J4: =DATAENTRY!D6 -> Chereponi West | Q4: HEAD TEACHER'S NAME: | W4: FEKPE PATRICK | AC4: SCHOOL'S GPS ADDRESS: | AI4: NC-2928-2802 | AP4: MALE: | AT4: =DATAENTRY!D8 -> 3 | CW4: THE SUMMATIVE ATTENDANCE AND COMMENT SECTION
B5: REGION: | C5: =DATAENTRY!H6 -> North East | E5: COMMUNITY: | J5: =DATAENTRY!D7 -> Ando-Nymanu | Q5: CLASS/FORM TEACHER: | W5: FEKPE JOHN | AC5: CLASS/FORM SIZE: | AI5: =DATAENTRY!H8 -> 6 | AP5: FEMALE: | AT5: =DATAENTRY!F8 -> 3
B6: DISTRICT: | C6: =DATAENTRY!H7 -> Chereponi | E6: SCHOOL NAME: | J6: =DATAENTRY!B2 -> jokpe School complex | Q6: TELEPHONE NUMBERS: | W6: 241224773 | AC6: AVERAGE AGE: | AI6: =DATAENTRY!K8 -> 15 | AP6: TOTAL: | AT6: 45
B7: CLASS/FORM: | C7: =DATAENTRY!D5 -> Basic 6
B8: YEAR: | C8: =DATAENTRY!I9 -> 2026 | F8: 1ST WEEK | L8: 2ND WEEK | R8: 3RD WEEK | X8: 4TH WEEK | AD8: 5TH WEEK | AJ8: 6TH WEEK | AP8: 7TH WEEK | AV8: 8TH WEEK | BB8: 9TH WEEK | BH8: 10TH WEEK | BN8: 11TH WEEK | BT8: 12TH WEEK | BZ8: 13TH WEEK | CF8: 14TH WEEK | CL8: 15TH WEEK | CR8: 16TH WEEK
B9: ATTENDANCE REGISTER | D9: MONTHS: | E9: >>> | F9: FABRUARY | K9: >>> | L9: FABRUARY | Q9: >>> | R9: FABRUARY | W9: >>> | X9: FABRUARY | AC9: >>> | AD9: FABRUARY | AI9: >>> | AJ9: FABRUARY | AO9: >>> | AP9: FABRUARY | AU9: >>> | AV9: FABRUARY | BA9: >>> | BB9: FABRUARY | BG9: >>> | BH9: FABRUARY | BM9: >>> | BN9: FABRUARY | BS9: >>> | BT9: FABRUARY | BY9: >>> | BZ9: FABRUARY | CE9: >>> | CF9: FABRUARY | CK9: >>> | CL9: FABRUARY | CQ9: >>> | CR9: FABRUARY
B10: BY FEKPE JOHN (+233241224773) | C10: DATES : | E10: 1st | F10: 2nd | G10: 3rd | H10: 4th | I10: 5th | J10: Date: | K10: 1st | L10: 2nd | M10: 3rd | N10: 4th | O10: 5th | P10: Date: | Q10: 1st | R10: 2nd | S10: 3rd | T10: 4th | U10: 5th | V10: Date: | W10: 1st | X10: 2nd | Y10: 3rd | Z10: 4th | AA10: 5th | AB10: Date: | AC10: 1st | AD10: 2nd | AE10: 3rd | AF10: 4th | AG10: 5th | AH10: Date: | AI10: 1st | AJ10: 2nd | AK10: 3rd | AL10: 4th | AM10: 5th | AN10: Date: | AO10: 1st | AP10: 2nd | AQ10: 3rd | AR10: 4th | AS10: 5th | AT10: Date: | AU10: 1st | AV10: 2nd | AW10: 3rd | AX10: 4th | AY10: 5th | AZ10: Date: | BA10: 1st | BB10: 2nd | BC10: 3rd | BD10: 4th | BE10: 5th | BF10: Date: | BG10: 1st | BH10: 2nd | BI10: 3rd | BJ10: 4th | BK10: 5th | BL10: Date: | BM10: 1st | BN10: 2nd | BO10: 3rd | BP10: 4th | BQ10: 5th | BR10: Date: | BS10: 1st | BT10: 2nd | BU10: 3rd | BV10: 4th | BW10: 5th | BX10: Date: | BY10: 1st | BZ10: 2nd | CA10: 3rd | CB10: 4th | CC10: 5th | CD10: Date: | CE10: 1st | CF10: 2nd | CG10: 3rd | CH10: 4th | CI10: 5th | CJ10: Date: | CK10: 1st | CL10: 2nd | CM10: 3rd | CN10: 4th | CO10: 5th | CP10: Date: | CQ10: 1st | CR10: 2nd | CS10: 3rd | CT10: 4th | CU10: 5th
B11: NAME OF STUDENTS | C11: SEX | D11: REG. NO | E11: M | F11: T | G11: W | H11: T | I11: F | J11: TOTAL | K11: M | L11: T | M11: W | N11: T | O11: F | P11: TOTAL | Q11: M | R11: T | S11: W | T11: T | U11: F | V11: TOTAL | W11: M | X11: T | Y11: W | Z11: T | AA11: F | AB11: TOTAL | AC11: M | AD11: T | AE11: W | AF11: T | AG11: F | AH11: TOTAL | AI11: M | AJ11: T | AK11: W | AL11: T | AM11: F | AN11: TOTAL | AO11: M | AP11: T | AQ11: W | AR11: T | AS11: F | AT11: TOTAL | AU11: M | AV11: T | AW11: W | AX11: T | AY11: F | AZ11: TOTAL | BA11: M | BB11: T | BC11: W | BD11: T | BE11: F | BF11: TOTAL | BG11: M | BH11: T | BI11: W | BJ11: T | BK11: F | BL11: TOTAL | BM11: M | BN11: T | BO11: W | BP11: T | BQ11: F | BR11: TOTAL | BS11: M | BT11: T | BU11: W | BV11: T | BW11: F | BX11: TOTAL | BY11: M | BZ11: T | CA11: W | CB11: T | CC11: F | CD11: TOTAL | CE11: M | CF11: T | CG11: W | CH11: T | CI11: F | CJ11: TOTAL | CK11: M | CL11: T | CM11: W | CN11: T | CO11: F | CP11: TOTAL | CQ11: M | CR11: T | CS11: W | CT11: T | CU11: F | CV11: TOTAL | CW11: Auto/Att. | CX11: COMMENT
B12: =IF(DATAENTRY!C12="","",DATAENTRY!C12) -> KOFI AKPALU | C12: =IF(DATAENTRY!D12="","",DATAENTRY!D12) -> M | D12: 1 | E12: 1 | F12: 0 | G12: 1 | H12: 1 | J12: =IF(C12="","",SUM(E12:I12)) -> 3 | P12: =IF(C12="","",SUM(K12:O12)+J12) -> 3 | V12: =IF(C12="","",SUM(Q12:U12)+P12) -> 3 | AB12: =IF(C12="","",SUM(W12:AA12)+V12) -> 3 | AH12: =IF(C12="","",SUM(AC12:AG12)+AB12) -> 3 | AN12: =IF(C12="","",SUM(AI12:AM12)+AH12) -> 3 | AT12: =IF(C12="","",SUM(AO12:AS12)+AN12) -> 3 | AZ12: =IF(C12="","",SUM(AU12:AY12)+AT12) -> 3 | BF12: =IF(C12="","",SUM(BA12:BE12)+AZ12) -> 3 | BL12: =IF(C12="","",SUM(BG12:BK12)+BF12) -> 3 | BR12: =IF(C12="","",SUM(BM12:BQ12)+BL12) -> 3 | BX12: =IF(C12="","",SUM(BS12:BW12)+BR12) -> 3 | CD12: =IF(C12="","",SUM(BY12:CC12)+BX12) -> 3 | CJ12: =IF(C12="","",SUM(CE12:CI12)+CD12) -> 3 | CP12: =IF(C12="","",SUM(CK12:CO12)+CJ12) -> 3 | CV12: =IF(C12="","",SUM(CQ12:CU12)+CP12) -> 3 | CW12: =CV12 -> 3 | CX12: =IF(CW12>=0.9*CX58,"Excellent ",IF(CW12>=0.8*CX58,"Regular",IF(CW12>=0.6*CX58,"Average",IF(CW12>=0.4*CX58,"Irregular ",IF(CW12>=0.2*CX58,"Poor ",IF(CW12>=0.1*CX58,"Trying To Drop",IF(CW12>=0,"Droping Out"))))))) -> Average
B13: =IF(DATAENTRY!C13="","",DATAENTRY!C13) -> AMA JULIAM | C13: =IF(DATAENTRY!D13="","",DATAENTRY!D13) -> F | D13: 2 | E13: 0 | F13: 1 | G13: 1 | H13: 0 | J13: =IF(C13="","",SUM(E13:I13)) -> 2 | P13: =IF(C13="","",SUM(K13:O13)+J13) -> 2 | V13: =IF(C13="","",SUM(Q13:U13)+P13) -> 2 | AB13: =IF(C13="","",SUM(W13:AA13)+V13) -> 2 | AH13: =IF(C13="","",SUM(AC13:AG13)+AB13) -> 2 | AN13: =IF(C13="","",SUM(AI13:AM13)+AH13) -> 2 | AT13: =IF(C13="","",SUM(AO13:AS13)+AN13) -> 2 | AZ13: =IF(C13="","",SUM(AU13:AY13)+AT13) -> 2 | BF13: =IF(C13="","",SUM(BA13:BE13)+AZ13) -> 2 | BL13: =IF(C13="","",SUM(BG13:BK13)+BF13) -> 2 | BR13: =IF(C13="","",SUM(BM13:BQ13)+BL13) -> 2 | BX13: =IF(C13="","",SUM(BS13:BW13)+BR13) -> 2 | CD13: =IF(C13="","",SUM(BY13:CC13)+BX13) -> 2 | CJ13: =IF(C13="","",SUM(CE13:CI13)+CD13) -> 2 | CP13: =IF(C13="","",SUM(CK13:CO13)+CJ13) -> 2 | CV13: =IF(C13="","",SUM(CQ13:CU13)+CP13) -> 2 | CW13: =CV13 -> 2 | CX13: =IF(CW13>=0.9*CX58,"Excellent ",IF(CW13>=0.8*CX58,"Regular",IF(CW13>=0.6*CX58,"Average",IF(CW13>=0.4*CX58,"Irregular ",IF(CW13>=0.2*CX58,"Poor ",IF(CW13>=0.1*CX58,"Trying To Drop",IF(CW13>=0,"Droping Out"))))))) -> Irregular
B14: =IF(DATAENTRY!C14="","",DATAENTRY!C14) -> KOKU BONTO | C14: =IF(DATAENTRY!D14="","",DATAENTRY!D14) -> M | D14: 3 | E14: 1 | F14: 1 | G14: 1 | H14: 1 | J14: =IF(C14="","",SUM(E14:I14)) -> 4 | P14: =IF(C14="","",SUM(K14:O14)+J14) -> 4 | V14: =IF(C14="","",SUM(Q14:U14)+P14) -> 4 | AB14: =IF(C14="","",SUM(W14:AA14)+V14) -> 4 | AH14: =IF(C14="","",SUM(AC14:AG14)+AB14) -> 4 | AN14: =IF(C14="","",SUM(AI14:AM14)+AH14) -> 4 | AT14: =IF(C14="","",SUM(AO14:AS14)+AN14) -> 4 | AZ14: =IF(C14="","",SUM(AU14:AY14)+AT14) -> 4 | BF14: =IF(C14="","",SUM(BA14:BE14)+AZ14) -> 4 | BL14: =IF(C14="","",SUM(BG14:BK14)+BF14) -> 4 | BR14: =IF(C14="","",SUM(BM14:BQ14)+BL14) -> 4 | BX14: =IF(C14="","",SUM(BS14:BW14)+BR14) -> 4 | CD14: =IF(C14="","",SUM(BY14:CC14)+BX14) -> 4 | CJ14: =IF(C14="","",SUM(CE14:CI14)+CD14) -> 4 | CP14: =IF(C14="","",SUM(CK14:CO14)+CJ14) -> 4 | CV14: =IF(C14="","",SUM(CQ14:CU14)+CP14) -> 4 | CW14: =CV14 -> 4
B15: =IF(DATAENTRY!C15="","",DATAENTRY!C15) -> DODOUKWE CHABA | C15: =IF(DATAENTRY!D15="","",DATAENTRY!D15) -> F | D15: 4 | E15: 1 | F15: 0 | G15: 1 | H15: 1 | J15: =IF(C15="","",SUM(E15:I15)) -> 3 | P15: =IF(C15="","",SUM(K15:O15)+J15) -> 3 | V15: =IF(C15="","",SUM(Q15:U15)+P15) -> 3 | AB15: =IF(C15="","",SUM(W15:AA15)+V15) -> 3 | AH15: =IF(C15="","",SUM(AC15:AG15)+AB15) -> 3 | AN15: =IF(C15="","",SUM(AI15:AM15)+AH15) -> 3 | AT15: =IF(C15="","",SUM(AO15:AS15)+AN15) -> 3 | AZ15: =IF(C15="","",SUM(AU15:AY15)+AT15) -> 3 | BF15: =IF(C15="","",SUM(BA15:BE15)+AZ15) -> 3 | BL15: =IF(C15="","",SUM(BG15:BK15)+BF15) -> 3 | BR15: =IF(C15="","",SUM(BM15:BQ15)+BL15) -> 3 | BX15: =IF(C15="","",SUM(BS15:BW15)+BR15) -> 3 | CD15: =IF(C15="","",SUM(BY15:CC15)+BX15) -> 3 | CJ15: =IF(C15="","",SUM(CE15:CI15)+CD15) -> 3 | CP15: =IF(C15="","",SUM(CK15:CO15)+CJ15) -> 3 | CV15: =IF(C15="","",SUM(CQ15:CU15)+CP15) -> 3 | CW15: =CV15 -> 3
B16: =IF(DATAENTRY!C16="","",DATAENTRY!C16) -> AMINA FRIDAY | C16: =IF(DATAENTRY!D16="","",DATAENTRY!D16) -> M | D16: 5 | J16: =IF(C16="","",SUM(E16:I16)) -> 0 | P16: =IF(C16="","",SUM(K16:O16)+J16) -> 0 | V16: =IF(C16="","",SUM(Q16:U16)+P16) -> 0 | AB16: =IF(C16="","",SUM(W16:AA16)+V16) -> 0 | AH16: =IF(C16="","",SUM(AC16:AG16)+AB16) -> 0 | AN16: =IF(C16="","",SUM(AI16:AM16)+AH16) -> 0 | AT16: =IF(C16="","",SUM(AO16:AS16)+AN16) -> 0 | AZ16: =IF(C16="","",SUM(AU16:AY16)+AT16) -> 0 | BF16: =IF(C16="","",SUM(BA16:BE16)+AZ16) -> 0 | BL16: =IF(C16="","",SUM(BG16:BK16)+BF16) -> 0 | BR16: =IF(C16="","",SUM(BM16:BQ16)+BL16) -> 0 | BX16: =IF(C16="","",SUM(BS16:BW16)+BR16) -> 0 | CD16: =IF(C16="","",SUM(BY16:CC16)+BX16) -> 0 | CJ16: =IF(C16="","",SUM(CE16:CI16)+CD16) -> 0 | CP16: =IF(C16="","",SUM(CK16:CO16)+CJ16) -> 0 | CV16: =IF(C16="","",SUM(CQ16:CU16)+CP16) -> 0 | CW16: =CV16 -> 0
B17: =IF(DATAENTRY!C17="","",DATAENTRY!C17) -> BABA NINJA | C17: =IF(DATAENTRY!D17="","",DATAENTRY!D17) -> F | D17: 6 | J17: =IF(C17="","",SUM(E17:I17)) -> 0 | P17: =IF(C17="","",SUM(K17:O17)+J17) -> 0 | V17: =IF(C17="","",SUM(Q17:U17)+P17) -> 0 | AB17: =IF(C17="","",SUM(W17:AA17)+V17) -> 0 | AH17: =IF(C17="","",SUM(AC17:AG17)+AB17) -> 0 | AN17: =IF(C17="","",SUM(AI17:AM17)+AH17) -> 0 | AT17: =IF(C17="","",SUM(AO17:AS17)+AN17) -> 0 | AZ17: =IF(C17="","",SUM(AU17:AY17)+AT17) -> 0 | BF17: =IF(C17="","",SUM(BA17:BE17)+AZ17) -> 0 | BL17: =IF(C17="","",SUM(BG17:BK17)+BF17) -> 0 | BR17: =IF(C17="","",SUM(BM17:BQ17)+BL17) -> 0 | BX17: =IF(C17="","",SUM(BS17:BW17)+BR17) -> 0 | CD17: =IF(C17="","",SUM(BY17:CC17)+BX17) -> 0 | CJ17: =IF(C17="","",SUM(CE17:CI17)+CD17) -> 0 | CP17: =IF(C17="","",SUM(CK17:CO17)+CJ17) -> 0 | CV17: =IF(C17="","",SUM(CQ17:CU17)+CP17) -> 0 | CW17: =CV17 -> 0
B18: =IF(DATAENTRY!C18="","",DATAENTRY!C18) | C18: =IF(DATAENTRY!D18="","",DATAENTRY!D18) | D18: 7 | J18: =IF(C18="","",SUM(E18:I18)) | P18: =IF(C18="","",SUM(K18:O18)+J18) | V18: =IF(C18="","",SUM(Q18:U18)+P18) | AB18: =IF(C18="","",SUM(W18:AA18)+V18) | AH18: =IF(C18="","",SUM(AC18:AG18)+AB18) | AN18: =IF(C18="","",SUM(AI18:AM18)+AH18) | AT18: =IF(C18="","",SUM(AO18:AS18)+AN18) | AZ18: =IF(C18="","",SUM(AU18:AY18)+AT18) | BF18: =IF(C18="","",SUM(BA18:BE18)+AZ18) | BL18: =IF(C18="","",SUM(BG18:BK18)+BF18) | BR18: =IF(C18="","",SUM(BM18:BQ18)+BL18) | BX18: =IF(C18="","",SUM(BS18:BW18)+BR18) | CD18: =IF(C18="","",SUM(BY18:CC18)+BX18) | CJ18: =IF(C18="","",SUM(CE18:CI18)+CD18) | CP18: =IF(C18="","",SUM(CK18:CO18)+CJ18) | CV18: =IF(C18="","",SUM(CQ18:CU18)+CP18) | CW18: =CV18
B19: =IF(DATAENTRY!C19="","",DATAENTRY!C19) | C19: =IF(DATAENTRY!D19="","",DATAENTRY!D19) | D19: 8 | J19: =IF(C19="","",SUM(E19:I19)) | P19: =IF(C19="","",SUM(K19:O19)+J19) | V19: =IF(C19="","",SUM(Q19:U19)+P19) | AB19: =IF(C19="","",SUM(W19:AA19)+V19) | AH19: =IF(C19="","",SUM(AC19:AG19)+AB19) | AN19: =IF(C19="","",SUM(AI19:AM19)+AH19) | AT19: =IF(C19="","",SUM(AO19:AS19)+AN19) | AZ19: =IF(C19="","",SUM(AU19:AY19)+AT19) | BF19: =IF(C19="","",SUM(BA19:BE19)+AZ19) | BL19: =IF(C19="","",SUM(BG19:BK19)+BF19) | BR19: =IF(C19="","",SUM(BM19:BQ19)+BL19) | BX19: =IF(C19="","",SUM(BS19:BW19)+BR19) | CD19: =IF(C19="","",SUM(BY19:CC19)+BX19) | CJ19: =IF(C19="","",SUM(CE19:CI19)+CD19) | CP19: =IF(C19="","",SUM(CK19:CO19)+CJ19) | CV19: =IF(C19="","",SUM(CQ19:CU19)+CP19) | CW19: =CV19
B20: =IF(DATAENTRY!C20="","",DATAENTRY!C20) | C20: =IF(DATAENTRY!D20="","",DATAENTRY!D20) | D20: 9 | J20: =IF(C20="","",SUM(E20:I20)) | P20: =IF(C20="","",SUM(K20:O20)+J20) | V20: =IF(C20="","",SUM(Q20:U20)+P20) | AB20: =IF(C20="","",SUM(W20:AA20)+V20) | AH20: =IF(C20="","",SUM(AC20:AG20)+AB20) | AN20: =IF(C20="","",SUM(AI20:AM20)+AH20) | AT20: =IF(C20="","",SUM(AO20:AS20)+AN20) | AZ20: =IF(C20="","",SUM(AU20:AY20)+AT20) | BF20: =IF(C20="","",SUM(BA20:BE20)+AZ20) | BL20: =IF(C20="","",SUM(BG20:BK20)+BF20) | BR20: =IF(C20="","",SUM(BM20:BQ20)+BL20) | BX20: =IF(C20="","",SUM(BS20:BW20)+BR20) | CD20: =IF(C20="","",SUM(BY20:CC20)+BX20) | CJ20: =IF(C20="","",SUM(CE20:CI20)+CD20) | CP20: =IF(C20="","",SUM(CK20:CO20)+CJ20) | CV20: =IF(C20="","",SUM(CQ20:CU20)+CP20) | CW20: =CV20
B21: =IF(DATAENTRY!C21="","",DATAENTRY!C21) | C21: =IF(DATAENTRY!D21="","",DATAENTRY!D21) | D21: 10 | J21: =IF(C21="","",SUM(E21:I21)) | P21: =IF(C21="","",SUM(K21:O21)+J21) | V21: =IF(C21="","",SUM(Q21:U21)+P21) | AB21: =IF(C21="","",SUM(W21:AA21)+V21) | AH21: =IF(C21="","",SUM(AC21:AG21)+AB21) | AN21: =IF(C21="","",SUM(AI21:AM21)+AH21) | AT21: =IF(C21="","",SUM(AO21:AS21)+AN21) | AZ21: =IF(C21="","",SUM(AU21:AY21)+AT21) | BF21: =IF(C21="","",SUM(BA21:BE21)+AZ21) | BL21: =IF(C21="","",SUM(BG21:BK21)+BF21) | BR21: =IF(C21="","",SUM(BM21:BQ21)+BL21) | BX21: =IF(C21="","",SUM(BS21:BW21)+BR21) | CD21: =IF(C21="","",SUM(BY21:CC21)+BX21) | CJ21: =IF(C21="","",SUM(CE21:CI21)+CD21) | CP21: =IF(C21="","",SUM(CK21:CO21)+CJ21) | CV21: =IF(C21="","",SUM(CQ21:CU21)+CP21) | CW21: =CV21
B22: =IF(DATAENTRY!C22="","",DATAENTRY!C22) | C22: =IF(DATAENTRY!D22="","",DATAENTRY!D22) | D22: 11 | J22: =IF(C22="","",SUM(E22:I22)) | P22: =IF(C22="","",SUM(K22:O22)+J22) | V22: =IF(C22="","",SUM(Q22:U22)+P22) | AB22: =IF(C22="","",SUM(W22:AA22)+V22) | AH22: =IF(C22="","",SUM(AC22:AG22)+AB22) | AN22: =IF(C22="","",SUM(AI22:AM22)+AH22) | AT22: =IF(C22="","",SUM(AO22:AS22)+AN22) | AZ22: =IF(C22="","",SUM(AU22:AY22)+AT22) | BF22: =IF(C22="","",SUM(BA22:BE22)+AZ22) | BL22: =IF(C22="","",SUM(BG22:BK22)+BF22) | BR22: =IF(C22="","",SUM(BM22:BQ22)+BL22) | BX22: =IF(C22="","",SUM(BS22:BW22)+BR22) | CD22: =IF(C22="","",SUM(BY22:CC22)+BX22) | CJ22: =IF(C22="","",SUM(CE22:CI22)+CD22) | CP22: =IF(C22="","",SUM(CK22:CO22)+CJ22) | CV22: =IF(C22="","",SUM(CQ22:CU22)+CP22) | CW22: =CV22
B23: =IF(DATAENTRY!C23="","",DATAENTRY!C23) | C23: =IF(DATAENTRY!D23="","",DATAENTRY!D23) | D23: 12 | J23: =IF(C23="","",SUM(E23:I23)) | P23: =IF(C23="","",SUM(K23:O23)+J23) | V23: =IF(C23="","",SUM(Q23:U23)+P23) | AB23: =IF(C23="","",SUM(W23:AA23)+V23) | AH23: =IF(C23="","",SUM(AC23:AG23)+AB23) | AN23: =IF(C23="","",SUM(AI23:AM23)+AH23) | AT23: =IF(C23="","",SUM(AO23:AS23)+AN23) | AZ23: =IF(C23="","",SUM(AU23:AY23)+AT23) | BF23: =IF(C23="","",SUM(BA23:BE23)+AZ23) | BL23: =IF(C23="","",SUM(BG23:BK23)+BF23) | BR23: =IF(C23="","",SUM(BM23:BQ23)+BL23) | BX23: =IF(C23="","",SUM(BS23:BW23)+BR23) | CD23: =IF(C23="","",SUM(BY23:CC23)+BX23) | CJ23: =IF(C23="","",SUM(CE23:CI23)+CD23) | CP23: =IF(C23="","",SUM(CK23:CO23)+CJ23) | CV23: =IF(C23="","",SUM(CQ23:CU23)+CP23) | CW23: =CV23
B24: =IF(DATAENTRY!C24="","",DATAENTRY!C24) | C24: =IF(DATAENTRY!D24="","",DATAENTRY!D24) | D24: 13 | J24: =IF(C24="","",SUM(E24:I24)) | P24: =IF(C24="","",SUM(K24:O24)+J24) | V24: =IF(C24="","",SUM(Q24:U24)+P24) | AB24: =IF(C24="","",SUM(W24:AA24)+V24) | AH24: =IF(C24="","",SUM(AC24:AG24)+AB24) | AN24: =IF(C24="","",SUM(AI24:AM24)+AH24) | AT24: =IF(C24="","",SUM(AO24:AS24)+AN24) | AZ24: =IF(C24="","",SUM(AU24:AY24)+AT24) | BF24: =IF(C24="","",SUM(BA24:BE24)+AZ24) | BL24: =IF(C24="","",SUM(BG24:BK24)+BF24) | BR24: =IF(C24="","",SUM(BM24:BQ24)+BL24) | BX24: =IF(C24="","",SUM(BS24:BW24)+BR24) | CD24: =IF(C24="","",SUM(BY24:CC24)+BX24) | CJ24: =IF(C24="","",SUM(CE24:CI24)+CD24) | CP24: =IF(C24="","",SUM(CK24:CO24)+CJ24) | CV24: =IF(C24="","",SUM(CQ24:CU24)+CP24) | CW24: =CV24
B25: =IF(DATAENTRY!C25="","",DATAENTRY!C25) | C25: =IF(DATAENTRY!D25="","",DATAENTRY!D25) | D25: 14 | J25: =IF(C25="","",SUM(E25:I25)) | P25: =IF(C25="","",SUM(K25:O25)+J25) | V25: =IF(C25="","",SUM(Q25:U25)+P25) | AB25: =IF(C25="","",SUM(W25:AA25)+V25) | AH25: =IF(C25="","",SUM(AC25:AG25)+AB25) | AN25: =IF(C25="","",SUM(AI25:AM25)+AH25) | AT25: =IF(C25="","",SUM(AO25:AS25)+AN25) | AZ25: =IF(C25="","",SUM(AU25:AY25)+AT25) | BF25: =IF(C25="","",SUM(BA25:BE25)+AZ25) | BL25: =IF(C25="","",SUM(BG25:BK25)+BF25) | BR25: =IF(C25="","",SUM(BM25:BQ25)+BL25) | BX25: =IF(C25="","",SUM(BS25:BW25)+BR25) | CD25: =IF(C25="","",SUM(BY25:CC25)+BX25) | CJ25: =IF(C25="","",SUM(CE25:CI25)+CD25) | CP25: =IF(C25="","",SUM(CK25:CO25)+CJ25) | CV25: =IF(C25="","",SUM(CQ25:CU25)+CP25) | CW25: =CV25
B26: =IF(DATAENTRY!C26="","",DATAENTRY!C26) | C26: =IF(DATAENTRY!D26="","",DATAENTRY!D26) | D26: 15 | J26: =IF(C26="","",SUM(E26:I26)) | P26: =IF(C26="","",SUM(K26:O26)+J26) | V26: =IF(C26="","",SUM(Q26:U26)+P26) | AB26: =IF(C26="","",SUM(W26:AA26)+V26) | AH26: =IF(C26="","",SUM(AC26:AG26)+AB26) | AN26: =IF(C26="","",SUM(AI26:AM26)+AH26) | AT26: =IF(C26="","",SUM(AO26:AS26)+AN26) | AZ26: =IF(C26="","",SUM(AU26:AY26)+AT26) | BF26: =IF(C26="","",SUM(BA26:BE26)+AZ26) | BL26: =IF(C26="","",SUM(BG26:BK26)+BF26) | BR26: =IF(C26="","",SUM(BM26:BQ26)+BL26) | BX26: =IF(C26="","",SUM(BS26:BW26)+BR26) | CD26: =IF(C26="","",SUM(BY26:CC26)+BX26) | CJ26: =IF(C26="","",SUM(CE26:CI26)+CD26) | CP26: =IF(C26="","",SUM(CK26:CO26)+CJ26) | CV26: =IF(C26="","",SUM(CQ26:CU26)+CP26) | CW26: =CV26
B27: =IF(DATAENTRY!C27="","",DATAENTRY!C27) | C27: =IF(DATAENTRY!D27="","",DATAENTRY!D27) | D27: 16 | J27: =IF(C27="","",SUM(E27:I27)) | P27: =IF(C27="","",SUM(K27:O27)+J27) | V27: =IF(C27="","",SUM(Q27:U27)+P27) | AB27: =IF(C27="","",SUM(W27:AA27)+V27) | AH27: =IF(C27="","",SUM(AC27:AG27)+AB27) | AN27: =IF(C27="","",SUM(AI27:AM27)+AH27) | AT27: =IF(C27="","",SUM(AO27:AS27)+AN27) | AZ27: =IF(C27="","",SUM(AU27:AY27)+AT27) | BF27: =IF(C27="","",SUM(BA27:BE27)+AZ27) | BL27: =IF(C27="","",SUM(BG27:BK27)+BF27) | BR27: =IF(C27="","",SUM(BM27:BQ27)+BL27) | BX27: =IF(C27="","",SUM(BS27:BW27)+BR27) | CD27: =IF(C27="","",SUM(BY27:CC27)+BX27) | CJ27: =IF(C27="","",SUM(CE27:CI27)+CD27) | CP27: =IF(C27="","",SUM(CK27:CO27)+CJ27) | CV27: =IF(C27="","",SUM(CQ27:CU27)+CP27) | CW27: =CV27
... B56: =IF(DATAENTRY!C56="","",DATAENTRY!C56) | C56: =IF(DATAENTRY!D56="","",DATAENTRY!D56) | D56: 45 | J56: =IF(C56="","",SUM(E56:I56)) | P56: =IF(C56="","",SUM(K56:O56)+J56) | V56: =IF(C56="","",SUM(Q56:U56)+P56) | AB56: =IF(C56="","",SUM(W56:AA56)+V56) | AH56: =IF(C56="","",SUM(AC56:AG56)+AB56) | AN56: =IF(C56="","",SUM(AI56:AM56)+AH56) | AT56: =IF(C56="","",SUM(AO56:AS56)+AN56) | AZ56: =IF(C56="","",SUM(AU56:AY56)+AT56) | BF56: =IF(C56="","",SUM(BA56:BE56)+AZ56) | BL56: =IF(C56="","",SUM(BG56:BK56)+BF56) | BR56: =IF(C56="","",SUM(BM56:BQ56)+BL56) | BX56: =IF(C56="","",SUM(BS56:BW56)+BR56) | CD56: =IF(C56="","",SUM(BY56:CC56)+BX56) | CJ56: =IF(C56="","",SUM(CE56:CI56)+CD56) | CP56: =IF(C56="","",SUM(CK56:CO56)+CJ56) | CV56: =IF(C56="","",SUM(CQ56:CU56)+CP56) | CW56: =CV56
B57: Daily Attendance For Boys(B) | D57: 100 | E57: =IF(E12="","",SUMIF(C12:C56,"=M",E12:E56)) -> 2 | F57: =IF(F12="","",SUMIF(C12:C56,"=M",F12:F56)) -> 1 | G57: =IF(G12="","",SUMIF(C12:C56,"=M",G12:G56)) -> 2 | H57: =IF(H12="","",SUMIF(C12:C56,"=M",H12:H56)) -> 2 | I57: =IF(I12="","",SUMIF(C12:C56,"=M",I12:I56)) | J57: =IF(E57="","",SUM(E57:I57)) -> 7 | K57: =IF(K12="","",SUMIF(C12:C56,"=M",K12:K56)) | L57: =IF(L12="","",SUMIF(C12:C56,"=M",L12:L56)) | M57: =IF(M12="","",SUMIF(C12:C56,"=M",M12:M56)) | N57: =IF(N12="","",SUMIF(C12:C56,"=M",N12:N56)) | O57: =IF(O12="","",SUMIF(C12:C56,"=M",O12:O56)) | P57: =IF(K57="","",SUM(K57:O57)) | Q57: =IF(Q12="","",SUMIF(C12:C56,"=M",Q12:Q56)) | R57: =IF(R12="","",SUMIF(C12:C56,"=M",R12:R56)) | S57: =IF(S12="","",SUMIF(C12:C56,"=M",S12:S56)) | T57: =IF(T12="","",SUMIF(C12:C56,"=M",T12:T56)) | U57: =IF(U12="","",SUMIF(C12:C56,"=M",U12:U56)) | V57: =IF(Q57="","",SUM(Q57:U57)) | W57: =IF(W12="","",SUMIF(C12:C56,"=M",W12:W56)) | X57: =IF(X12="","",SUMIF(C12:C56,"=M",X12:X56)) | Y57: =IF(Y12="","",SUMIF(C12:C56,"=M",Y12:Y56)) | Z57: =IF(Z12="","",SUMIF(C12:C56,"=M",Z12:Z56)) | AA57: =IF(AA12="","",SUMIF(C12:C56,"=M",AA12:AA56)) | AB57: =IF(W57="","",SUM(W57:AA57)) | AC57: =IF(AC12="","",SUMIF(C12:C56,"=M",AC12:AC56)) | AD57: =IF(AD12="","",SUMIF(C12:C56,"=M",AD12:AD56)) | AE57: =IF(AE12="","",SUMIF(C12:C56,"=M",AE12:AE56)) | AF57: =IF(AF12="","",SUMIF(C12:C56,"=M",AF12:AF56)) | AG57: =IF(AG12="","",SUMIF(C12:C56,"=M",AG12:AG56)) | AH57: =IF(AC57="","",SUM(AC57:AG57)) | AI57: =IF(AI12="","",SUMIF(C12:C56,"=M",AI12:AI56)) | AJ57: =IF(AJ12="","",SUMIF(C12:C56,"=M",AJ12:AJ56)) | AK57: =IF(AK12="","",SUMIF(C12:C56,"=M",AK12:AK56)) | AL57: =IF(AL12="","",SUMIF(C12:C56,"=M",AL12:AL56)) | AM57: =IF(AM12="","",SUMIF(C12:C56,"=M",AM12:AM56)) | AN57: =IF(AI57="","",SUM(AI57:AM57)) | AO57: =IF(AO12="","",SUMIF(C12:C56,"=M",AO12:AO56)) | AP57: =IF(AP12="","",SUMIF(C12:C56,"=M",AP12:AP56)) | AQ57: =IF(AQ12="","",SUMIF(C12:C56,"=M",AQ12:AQ56)) | AR57: =IF(AR12="","",SUMIF(C12:C56,"=M",AR12:AR56)) | AS57: =IF(AS12="","",SUMIF(C12:C56,"=M",AS12:AS56)) | AT57: =IF(AO57="","",SUM(AO57:AS57)) | AU57: =IF(AU12="","",SUMIF(C12:C56,"=M",AU12:AU56)) | AV57: =IF(AV12="","",SUMIF(C12:C56,"=M",AV12:AV56)) | AW57: =IF(AW12="","",SUMIF(C12:C56,"=M",AW12:AW56)) | AX57: =IF(AX12="","",SUMIF(C12:C56,"=M",AX12:AX56)) | AY57: =IF(AY12="","",SUMIF(C12:C56,"=M",AY12:AY56)) | AZ57: =IF(AU57="","",SUM(AU57:AY57)) | BA57: =IF(BA12="","",SUMIF(C12:C56,"=M",BA12:BA56)) | BB57: =IF(BB12="","",SUMIF(C12:C56,"=M",BB12:BB56)) | BC57: =IF(BC12="","",SUMIF(C12:C56,"=M",BC12:BC56)) | BD57: =IF(BD12="","",SUMIF(C12:C56,"=M",BD12:BD56)) | BE57: =IF(BE12="","",SUMIF(C12:C56,"=M",BE12:BE56)) | BF57: =IF(BA57="","",SUM(BA57:BE57)) | BG57: =IF(BG12="","",SUMIF(C12:C56,"=M",BG12:BG56)) | BH57: =IF(BH12="","",SUMIF(C12:C56,"=M",BH12:BH56)) | BI57: =IF(BI12="","",SUMIF(C12:C56,"=M",BI12:BI56)) | BJ57: =IF(BJ12="","",SUMIF(C12:C56,"=M",BJ12:BJ56)) | BK57: =IF(BK12="","",SUMIF(C12:C56,"=M",BK12:BK56)) | BL57: =IF(BG57="","",SUM(BG57:BK57)) | BM57: =IF(BM12="","",SUMIF(C12:C56,"=M",BM12:BM56)) | BN57: =IF(BN12="","",SUMIF(C12:C56,"=M",BN12:BN56)) | BO57: =IF(BO12="","",SUMIF(C12:C56,"=M",BO12:BO56)) | BP57: =IF(BP12="","",SUMIF(C12:C56,"=M",BP12:BP56)) | BQ57: =IF(BQ12="","",SUMIF(C12:C56,"=M",BQ12:BQ56)) | BR57: =IF(BM57="","",SUM(BM57:BQ57)) | BS57: =IF(BS12="","",SUMIF(C12:C56,"=M",BS12:BS56)) | BT57: =IF(BT12="","",SUMIF(C12:C56,"=M",BT12:BT56)) | BU57: =IF(BU12="","",SUMIF(C12:C56,"=M",BU12:BU56)) | BV57: =IF(BV12="","",SUMIF(C12:C56,"=M",BV12:BV56)) | BW57: =IF(BW12="","",SUMIF(C12:C56,"=M",BW12:BW56)) | BX57: =IF(BS57="","",SUM(BS57:BW57)) | BY57: =IF(BY12="","",SUMIF(C12:C56,"=M",BY12:BY56)) | BZ57: =IF(BZ12="","",SUMIF(C12:C56,"=M",BZ12:BZ56)) | CA57: =IF(CA12="","",SUMIF(C12:C56,"=M",CA12:CA56)) | CB57: =IF(CB12="","",SUMIF(C12:C56,"=M",CB12:CB56)) | CC57: =IF(CC12="","",SUMIF(C12:C56,"=M",CC12:CC56)) | CD57: =IF(BY57="","",SUM(BY57:CC57)) | CE57: =IF(CE12="","",SUMIF(C12:C56,"=M",CE12:CE56)) | CF57: =IF(CF12="","",SUMIF(C12:C56,"=M",CF12:CF56)) | CG57: =IF(CG12="","",SUMIF(C12:C56,"=M",CG12:CG56)) | CH57: =IF(CH12="","",SUMIF(C12:C56,"=M",CH12:CH56)) | CI57: =IF(CI12="","",SUMIF(C12:C56,"=M",CI12:CI56)) | CJ57: =IF(CE57="","",SUM(CE57:CI57)) | CK57: =IF(CK12="","",SUMIF(C12:C56,"=M",CK12:CK56)) | CL57: =IF(CL12="","",SUMIF(C12:C56,"=M",CL12:CL56)) | CM57: =IF(CM12="","",SUMIF(C12:C56,"=M",CM12:CM56)) | CN57: =IF(CN12="","",SUMIF(C12:C56,"=M",CN12:CN56)) | CO57: =IF(CO12="","",SUMIF(C12:C56,"=M",CO12:CO56)) | CP57: =IF(CK57="","",SUM(CK57:CO57)) | CQ57: =IF(CQ12="","",SUMIF(C12:C56,"=M",CQ12:CQ56)) | CR57: =IF(CR12="","",SUMIF(C12:C56,"=M",CR12:CR56)) | CS57: =IF(CS12="","",SUMIF(C12:C56,"=M",CS12:CS56)) | CT57: =IF(CT12="","",SUMIF(C12:C56,"=M",CT12:CT56)) | CU57: =IF(CU12="","",SUMIF(C12:C56,"=M",CU12:CU56)) | CV57: =IF(CQ57="","",SUM(CQ57:CU57)) | CW57: Actual Att. (Auto) | CX57: Days Opened (Manu)
B58: Daily Attendance For Girls(G) | D58: >>>>> | E58: =IF(E12="","",SUMIF(C12:C56,"=F",E12:E56)) -> 1 | F58: =IF(F12="","",SUMIF(C12:C56,"=F",F12:F56)) -> 1 | G58: =IF(G12="","",SUMIF(C12:C56,"=F",G12:G56)) -> 2 | H58: =IF(H12="","",SUMIF(C12:C56,"=F",H12:H56)) -> 1 | I58: =IF(I12="","",SUMIF(C12:C56,"=F",I12:I56)) | J58: =IF(E58="","",SUM(E58:I58)) -> 5 | K58: =IF(K12="","",SUMIF(C12:C56,"=F",K12:K56)) | L58: =IF(L12="","",SUMIF(C12:C56,"=F",L12:L56)) | M58: =IF(M12="","",SUMIF(C12:C56,"=F",M12:M56)) | N58: =IF(N12="","",SUMIF(C12:C56,"=F",N12:N56)) | O58: =IF(O12="","",SUMIF(C12:C56,"=F",O12:O56)) | P58: =IF(K58="","",SUM(K58:O58)) | Q58: =IF(Q12="","",SUMIF(C12:C56,"=F",Q12:Q56)) | R58: =IF(R12="","",SUMIF(C12:C56,"=F",R12:R56)) | S58: =IF(S12="","",SUMIF(C12:C56,"=F",S12:S56)) | T58: =IF(T12="","",SUMIF(C12:C56,"=F",T12:T56)) | U58: =IF(U12="","",SUMIF(C12:C56,"=F",U12:U56)) | V58: =IF(Q58="","",SUM(Q58:U58)) | W58: =IF(W12="","",SUMIF(C12:C56,"=F",W12:W56)) | X58: =IF(X12="","",SUMIF(C12:C56,"=F",X12:X56)) | Y58: =IF(Y12="","",SUMIF(C12:C56,"=F",Y12:Y56)) | Z58: =IF(Z12="","",SUMIF(C12:C56,"=F",Z12:Z56)) | AA58: =IF(AA12="","",SUMIF(C12:C56,"=F",AA12:AA56)) | AB58: =IF(W58="","",SUM(W58:AA58)) | AC58: =IF(AC12="","",SUMIF(C12:C56,"=F",AC12:AC56)) | AD58: =IF(AD12="","",SUMIF(C12:C56,"=F",AD12:AD56)) | AE58: =IF(AE12="","",SUMIF(C12:C56,"=F",AE12:AE56)) | AF58: =IF(AF12="","",SUMIF(C12:C56,"=F",AF12:AF56)) | AG58: =IF(AG12="","",SUMIF(C12:C56,"=F",AG12:AG56)) | AH58: =IF(AC58="","",SUM(AC58:AG58)) | AI58: =IF(AI12="","",SUMIF(C12:C56,"=F",AI12:AI56)) | AJ58: =IF(AJ12="","",SUMIF(C12:C56,"=F",AJ12:AJ56)) | AK58: =IF(AK12="","",SUMIF(C12:C56,"=F",AK12:AK56)) | AL58: =IF(AL12="","",SUMIF(C12:C56,"=F",AL12:AL56)) | AM58: =IF(AM12="","",SUMIF(C12:C56,"=F",AM12:AM56)) | AN58: =IF(AI58="","",SUM(AI58:AM58)) | AO58: =IF(AO12="","",SUMIF(C12:C56,"=F",AO12:AO56)) | AP58: =IF(AP12="","",SUMIF(C12:C56,"=F",AP12:AP56)) | AQ58: =IF(AQ12="","",SUMIF(C12:C56,"=F",AQ12:AQ56)) | AR58: =IF(AR12="","",SUMIF(C12:C56,"=F",AR12:AR56)) | AS58: =IF(AS12="","",SUMIF(C12:C56,"=F",AS12:AS56)) | AT58: =IF(AO58="","",SUM(AO58:AS58)) | AU58: =IF(AU12="","",SUMIF(C12:C56,"=F",AU12:AU56)) | AV58: =IF(AV12="","",SUMIF(C12:C56,"=F",AV12:AV56)) | AW58: =IF(AW12="","",SUMIF(C12:C56,"=F",AW12:AW56)) | AX58: =IF(AX12="","",SUMIF(C12:C56,"=F",AX12:AX56)) | AY58: =IF(AY12="","",SUMIF(C12:C56,"=F",AY12:AY56)) | AZ58: =IF(AU58="","",SUM(AU58:AY58)) | BA58: =IF(BA12="","",SUMIF(C12:C56,"=F",BA12:BA56)) | BB58: =IF(BB12="","",SUMIF(C12:C56,"=F",BB12:BB56)) | BC58: =IF(BC12="","",SUMIF(C12:C56,"=F",BC12:BC56)) | BD58: =IF(BD12="","",SUMIF(C12:C56,"=F",BD12:BD56)) | BE58: =IF(BE12="","",SUMIF(C12:C56,"=F",BE12:BE56)) | BF58: =IF(BA58="","",SUM(BA58:BE58)) | BG58: =IF(BG12="","",SUMIF(C12:C56,"=F",BG12:BG56)) | BH58: =IF(BH12="","",SUMIF(C12:C56,"=F",BH12:BH56)) | BI58: =IF(BI12="","",SUMIF(C12:C56,"=F",BI12:BI56)) | BJ58: =IF(BJ12="","",SUMIF(C12:C56,"=F",BJ12:BJ56)) | BK58: =IF(BK12="","",SUMIF(C12:C56,"=F",BK12:BK56)) | BL58: =IF(BG58="","",SUM(BG58:BK58)) | BM58: =IF(BM12="","",SUMIF(C12:C56,"=F",BM12:BM56)) | BN58: =IF(BN12="","",SUMIF(C12:C56,"=F",BN12:BN56)) | BO58: =IF(BO12="","",SUMIF(C12:C56,"=F",BO12:BO56)) | BP58: =IF(BP12="","",SUMIF(C12:C56,"=F",BP12:BP56)) | BQ58: =IF(BQ12="","",SUMIF(C12:C56,"=F",BQ12:BQ56)) | BR58: =IF(BM58="","",SUM(BM58:BQ58)) | BS58: =IF(BS12="","",SUMIF(C12:C56,"=F",BS12:BS56)) | BT58: =IF(BT12="","",SUMIF(C12:C56,"=F",BT12:BT56)) | BU58: =IF(BU12="","",SUMIF(C12:C56,"=F",BU12:BU56)) | BV58: =IF(BV12="","",SUMIF(C12:C56,"=F",BV12:BV56)) | BW58: =IF(BW12="","",SUMIF(C12:C56,"=F",BW12:BW56)) | BX58: =IF(BS58="","",SUM(BS58:BW58)) | BY58: =IF(BY12="","",SUMIF(C12:C56,"=F",BY12:BY56)) | BZ58: =IF(BZ12="","",SUMIF(C12:C56,"=F",BZ12:BZ56)) | CA58: =IF(CA12="","",SUMIF(C12:C56,"=F",CA12:CA56)) | CB58: =IF(CB12="","",SUMIF(C12:C56,"=F",CB12:CB56)) | CC58: =IF(CC12="","",SUMIF(C12:C56,"=F",CC12:CC56)) | CD58: =IF(BY58="","",SUM(BY58:CC58)) | CE58: =IF(CE12="","",SUMIF(C12:C56,"=F",CE12:CE56)) | CF58: =IF(CF12="","",SUMIF(C12:C56,"=F",CF12:CF56)) | CG58: =IF(CG12="","",SUMIF(C12:C56,"=F",CG12:CG56)) | CH58: =IF(CH12="","",SUMIF(C12:C56,"=F",CH12:CH56)) | CI58: =IF(CI12="","",SUMIF(C12:C56,"=F",CI12:CI56)) | CJ58: =IF(CE58="","",SUM(CE58:CI58)) | CK58: =IF(CK12="","",SUMIF(C12:C56,"=F",CK12:CK56)) | CL58: =IF(CL12="","",SUMIF(C12:C56,"=F",CL12:CL56)) | CM58: =IF(CM12="","",SUMIF(C12:C56,"=F",CM12:CM56)) | CN58: =IF(CN12="","",SUMIF(C12:C56,"=F",CN12:CN56)) | CO58: =IF(CO12="","",SUMIF(C12:C56,"=F",CO12:CO56)) | CP58: =IF(CK58="","",SUM(CK58:CO58)) | CQ58: =IF(CQ12="","",SUMIF(C12:C56,"=F",CQ12:CQ56)) | CR58: =IF(CR12="","",SUMIF(C12:C56,"=F",CR12:CR56)) | CS58: =IF(CS12="","",SUMIF(C12:C56,"=F",CS12:CS56)) | CT58: =IF(CT12="","",SUMIF(C12:C56,"=F",CT12:CT56)) | CU58: =IF(CU12="","",SUMIF(C12:C56,"=F",CU12:CU56)) | CV58: =IF(CQ58="","",SUM(CQ58:CU58)) | CW58: =SUM(CW12:CW56) -> 12 | CX58: =CV60 -> 4
B59: Total Daily Attendance For(B+G) | D59: >>>>> | E59: =IF(E57="","",SUM(E57:E58)) -> 3 | F59: =IF(F57="","",SUM(F57:F58)) -> 2 | G59: =IF(G57="","",SUM(G57:G58)) -> 4 | H59: =IF(H57="","",SUM(H57:H58)) -> 3 | I59: =IF(I57="","",SUM(I57:I58)) | J59: =IF(E59="","",SUM(E59:I59)) -> 12 | K59: =IF(K57="","",SUM(K57:K58)) | L59: =IF(L57="","",SUM(L57:L58)) | M59: =IF(M57="","",SUM(M57:M58)) | N59: =IF(N57="","",SUM(N57:N58)) | O59: =IF(O57="","",SUM(O57:O58)) | P59: =IF(K59="","",SUM(K59:O59)) | Q59: =IF(Q57="","",SUM(Q57:Q58)) | R59: =IF(R57="","",SUM(R57:R58)) | S59: =IF(S57="","",SUM(S57:S58)) | T59: =IF(T57="","",SUM(T57:T58)) | U59: =IF(U57="","",SUM(U57:U58)) | V59: =IF(Q59="","",SUM(Q59:U59)) | W59: =IF(W57="","",SUM(W57:W58)) | X59: =IF(X57="","",SUM(X57:X58)) | Y59: =IF(Y57="","",SUM(Y57:Y58)) | Z59: =IF(Z57="","",SUM(Z57:Z58)) | AA59: =IF(AA57="","",SUM(AA57:AA58)) | AB59: =IF(W59="","",SUM(W59:AA59)) | AC59: =IF(AC57="","",SUM(AC57:AC58)) | AD59: =IF(AD57="","",SUM(AD57:AD58)) | AE59: =IF(AE57="","",SUM(AE57:AE58)) | AF59: =IF(AF57="","",SUM(AF57:AF58)) | AG59: =IF(AG57="","",SUM(AG57:AG58)) | AH59: =IF(AC59="","",SUM(AC59:AG59)) | AI59: =IF(AI57="","",SUM(AI57:AI58)) | AJ59: =IF(AJ57="","",SUM(AJ57:AJ58)) | AK59: =IF(AK57="","",SUM(AK57:AK58)) | AL59: =IF(AL57="","",SUM(AL57:AL58)) | AM59: =IF(AM57="","",SUM(AM57:AM58)) | AN59: =IF(AI59="","",SUM(AI59:AM59)) | AO59: =IF(AO57="","",SUM(AO57:AO58)) | AP59: =IF(AP57="","",SUM(AP57:AP58)) | AQ59: =IF(AQ57="","",SUM(AQ57:AQ58)) | AR59: =IF(AR57="","",SUM(AR57:AR58)) | AS59: =IF(AS57="","",SUM(AS57:AS58)) | AT59: =IF(AO59="","",SUM(AO59:AS59)) | AU59: =IF(AU57="","",SUM(AU57:AU58)) | AV59: =IF(AV57="","",SUM(AV57:AV58)) | AW59: =IF(AW57="","",SUM(AW57:AW58)) | AX59: =IF(AX57="","",SUM(AX57:AX58)) | AY59: =IF(AY57="","",SUM(AY57:AY58)) | AZ59: =IF(AU59="","",SUM(AU59:AY59)) | BA59: =IF(BA57="","",SUM(BA57:BA58)) | BB59: =IF(BB57="","",SUM(BB57:BB58)) | BC59: =IF(BC57="","",SUM(BC57:BC58)) | BD59: =IF(BD57="","",SUM(BD57:BD58)) | BE59: =IF(BE57="","",SUM(BE57:BE58)) | BF59: =IF(BA59="","",SUM(BA59:BE59)) | BG59: =IF(BG57="","",SUM(BG57:BG58)) | BH59: =IF(BH57="","",SUM(BH57:BH58)) | BI59: =IF(BI57="","",SUM(BI57:BI58)) | BJ59: =IF(BJ57="","",SUM(BJ57:BJ58)) | BK59: =IF(BK57="","",SUM(BK57:BK58)) | BL59: =IF(BG59="","",SUM(BG59:BK59)) | BM59: =IF(BM57="","",SUM(BM57:BM58)) | BN59: =IF(BN57="","",SUM(BN57:BN58)) | BO59: =IF(BO57="","",SUM(BO57:BO58)) | BP59: =IF(BP57="","",SUM(BP57:BP58)) | BQ59: =IF(BQ57="","",SUM(BQ57:BQ58)) | BR59: =IF(BM59="","",SUM(BM59:BQ59)) | BS59: =IF(BS57="","",SUM(BS57:BS58)) | BT59: =IF(BT57="","",SUM(BT57:BT58)) | BU59: =IF(BU57="","",SUM(BU57:BU58)) | BV59: =IF(BV57="","",SUM(BV57:BV58)) | BW59: =IF(BW57="","",SUM(BW57:BW58)) | BX59: =IF(BS59="","",SUM(BS59:BW59)) | BY59: =IF(BY57="","",SUM(BY57:BY58)) | BZ59: =IF(BZ57="","",SUM(BZ57:BZ58)) | CA59: =IF(CA57="","",SUM(CA57:CA58)) | CB59: =IF(CB57="","",SUM(CB57:CB58)) | CC59: =IF(CC57="","",SUM(CC57:CC58)) | CD59: =IF(BY59="","",SUM(BY59:CC59)) | CE59: =IF(CE57="","",SUM(CE57:CE58)) | CF59: =IF(CF57="","",SUM(CF57:CF58)) | CG59: =IF(CG57="","",SUM(CG57:CG58)) | CH59: =IF(CH57="","",SUM(CH57:CH58)) | CI59: =IF(CI57="","",SUM(CI57:CI58)) | CJ59: =IF(CE59="","",SUM(CE59:CI59)) | CK59: =IF(CK57="","",SUM(CK57:CK58)) | CL59: =IF(CL57="","",SUM(CL57:CL58)) | CM59: =IF(CM57="","",SUM(CM57:CM58)) | CN59: =IF(CN57="","",SUM(CN57:CN58)) | CO59: =IF(CO57="","",SUM(CO57:CO58)) | CP59: =IF(CK59="","",SUM(CK59:CO59)) | CQ59: =IF(CQ57="","",SUM(CQ57:CQ58)) | CR59: =IF(CR57="","",SUM(CR57:CR58)) | CS59: =IF(CS57="","",SUM(CS57:CS58)) | CT59: =IF(CT57="","",SUM(CT57:CT58)) | CU59: =IF(CU57="","",SUM(CU57:CU58)) | CV59: =IF(CQ59="","",SUM(CQ59:CU59)) | CW59: Att. Rate (Auto) | CX59: Exp Actual Att.
B60: Days Opened For The Week | D60: >>>>> | E60: >> | F60: =COUNTIF(E59:I59,">=1") -> 4 | I60: >> | J60: =IF(F60="","",F60) -> 4 | K60: >> | L60: =COUNTIF(K59:O59,">=1") -> 0 | O60: >> | P60: =IF(J60="","",SUM(J60+L60)) -> 4 | Q60: >> | R60: =COUNTIF(Q59:U59,">=1") -> 0 | U60: >> | V60: =IF(P60="","",SUM(P60+R60)) -> 4 | W60: >> | X60: =COUNTIF(W59:AA59,">=1") -> 0 | AA60: >> | AB60: =IF(V60="","",SUM(V60+X60)) -> 4 | AC60: >> | AD60: =COUNTIF(AC59:AG59,">=1") -> 0 | AG60: >> | AH60: =IF(AB60="","",SUM(AB60+AD60)) -> 4 | AI60: >> | AJ60: =COUNTIF(AI59:AM59,">=1") -> 0 | AM60: >> | AN60: =IF(AH60="","",SUM(AH60+AJ60)) -> 4 | AO60: >> | AP60: =COUNTIF(AO59:AS59,">=1") -> 0 | AS60: >> | AT60: =IF(AN60="","",SUM(AN60+AP60)) -> 4 | AU60: >> | AV60: =COUNTIF(AU59:AY59,">=1") -> 0 | AY60: >> | AZ60: =IF(AT60="","",SUM(AT60+AV60)) -> 4 | BA60: >> | BB60: =COUNTIF(BA59:BE59,">=1") -> 0 | BE60: >> | BF60: =IF(AZ60="","",SUM(AZ60+BB60)) -> 4 | BG60: >> | BH60: =COUNTIF(BG59:BK59,">=1") -> 0 | BK60: >> | BL60: =IF(BF60="","",SUM(BF60+BH60)) -> 4 | BM60: >> | BN60: =COUNTIF(BM59:BQ59,">=1") -> 0 | BQ60: >> | BR60: =IF(BL60="","",SUM(BL60+BN60)) -> 4 | BS60: >> | BT60: =COUNTIF(BS59:BW59,">=1") -> 0 | BW60: >> | BX60: =IF(BR60="","",SUM(BR60+BT60)) -> 4 | BY60: >> | BZ60: =COUNTIF(BY59:CC59,">=1") -> 0 | CC60: >> | CD60: =IF(BX60="","",SUM(BX60+BZ60)) -> 4 | CE60: >> | CF60: =COUNTIF(CE59:CI59,">=1") -> 0 | CI60: >> | CJ60: =IF(CD60="","",SUM(CD60+CF60)) -> 4 | CK60: >> | CL60: =COUNTIF(CK59:CO59,">=1") -> 0 | CO60: >> | CP60: =IF(CJ60="","",SUM(CJ60+CL60)) -> 4 | CQ60: >> | CR60: =COUNTIF(CQ59:CU59,">=1") -> 0 | CU60: >> | CV60: =IF(CP60="","",SUM(CP60+CR60)) -> 4 | CW60: =CW58/AT6 -> 0.26666667 | CX60: =AT6*CX58 -> 180
B61: Weekly Total For Boys(B)>>> | F61: =SUM(E57:I57) -> 7 | L61: =IF(K57="","",SUM(K57:O57)) | R61: =IF(Q57="","",SUM(Q57:U57)) | X61: =IF(W57="","",SUM(W57:AA57)) | AD61: =IF(AC57="","",SUM(AC57:AG57)) | AJ61: =IF(AI57="","",SUM(AI57:AM57)) | AP61: =IF(AO57="","",SUM(AO57:AS57)) | AV61: =IF(AU57="","",SUM(AU57:AY57)) | BB61: =IF(BA57="","",SUM(BA57:BE57)) | BH61: =IF(BG57="","",SUM(BG57:BK57)) | BN61: =IF(BM57="","",SUM(BM57:BQ57)) | BT61: =IF(BS57="","",SUM(BS57:BW57)) | BZ61: =IF(BY57="","",SUM(BY57:CC57)) | CF61: =IF(CE57="","",SUM(CE57:CI57)) | CL61: =IF(CK57="","",SUM(CK57:CO57)) | CR61: =IF(CQ57="","",SUM(CQ57:CU57))
B62: Weekly Total For Girls(G)>>> | F62: =SUM(E58:I58) -> 5 | L62: =IF(K58="","",SUM(K58:O58)) | R62: =IF(Q58="","",SUM(Q58:U58)) | X62: =IF(W58="","",SUM(W58:AA58)) | AD62: =IF(AC58="","",SUM(AC58:AG58)) | AJ62: =IF(AI58="","",SUM(AI58:AM58)) | AP62: =IF(AO58="","",SUM(AO58:AS58)) | AV62: =IF(AU58="","",SUM(AU58:AY58)) | BB62: =IF(BA58="","",SUM(BA58:BE58)) | BH62: =IF(BG58="","",SUM(BG58:BK58)) | BN62: =IF(BM58="","",SUM(BM58:BQ58)) | BT62: =IF(BS58="","",SUM(BS58:BW58)) | BZ62: =IF(BY58="","",SUM(BY58:CC58)) | CF62: =IF(CE58="","",SUM(CE58:CI58)) | CL62: =IF(CK58="","",SUM(CK58:CO58)) | CR62: =IF(CQ58="","",SUM(CQ58:CU58))
B63: Weekly Total For Boys&Girls (B+G)>>> | F63: =SUM(E59:I59) -> 12 | L63: =IF(K59="","",SUM(K59:O59)) | R63: =IF(Q59="","",SUM(Q59:U59)) | X63: =IF(W59="","",SUM(W59:AA59)) | AD63: =IF(AC59="","",SUM(AC59:AG59)) | AJ63: =IF(AI59="","",SUM(AI59:AM59)) | AP63: =IF(AO59="","",SUM(AO59:AS59)) | AV63: =IF(AU59="","",SUM(AU59:AY59)) | BB63: =IF(BA59="","",SUM(BA59:BE59)) | BH63: =IF(BG59="","",SUM(BG59:BK59)) | BN63: =IF(BM59="","",SUM(BM59:BQ59)) | BT63: =IF(BS59="","",SUM(BS59:BW59)) | BZ63: =IF(BY59="","",SUM(BY59:CC59)) | CF63: =IF(CE59="","",SUM(CE59:CI59)) | CL63: =IF(CK59="","",SUM(CK59:CO59)) | CR63: =IF(CQ59="","",SUM(CQ59:CU59))

Sheet REPORTCARD
B2: =SUMMARY!B2 -> jokpe School complex
C4: Student Report Card
C5: =YEAR(TODAY()) -> 2026
B6: NAME OF STUDENT: | C6: =IFERROR(INDEX(ENGLISH!C:C,MATCH(VALUE(J6),ENGLISH!B:B,0)),"") -> KOFI AKPALU | G6: ADMISSION NUMBER: | J6: 1
B7: CLASS: | C7: =SUMMARY!B5 -> Basic 6 | G7: GENDER: | J7: =IFERROR(INDEX(ENGLISH!D:D,MATCH(VALUE(J6),ENGLISH!B:B,0)),"") -> M
B8: TERM: | C8: =SUMMARY!C4 -> First Term | G8: DATE: | J8: =DATAENTRY!K9 -> 44275
C10: Continuous Assessement A 100% | G10: Test A 50% | H10: Exam B 100% | I10: Exam B 50% | J10: Total (A+B) 100% | K10: Grade | L10: Remarks
B11: SUBJECTS | C11: Test1 | D11: Test2 | E11: Test3 | F11: Test4
B12: =IF(ENGLISH!D7="","",ENGLISH!D7) -> ENGLISH LANGUAGE | C12: =IF(J7="","", IFERROR(INDEX(ENGLISH!E:E,MATCH(VALUE(J6),ENGLISH!B:B,0)),"")) -> 0 | D12: =IF(J7="","",IFERROR(INDEX(ENGLISH!F:F,MATCH(VALUE(J6),ENGLISH!B:B,0)),"")) -> 0 | E12: =IF(J7="","",IFERROR(INDEX(ENGLISH!G:G,MATCH(VALUE(J6),ENGLISH!B:B,0)),"")) -> 0 | F12: =IF(J7="","",IFERROR(INDEX(ENGLISH!H:H,MATCH(VALUE(J6),ENGLISH!B:B,0)),"")) -> 0 | G12: =IFERROR(INDEX(ENGLISH!J:J,MATCH(VALUE(J6),ENGLISH!B:B,0)),"") | H12: =IF(J7="","",IFERROR(INDEX(ENGLISH!K:K,MATCH(VALUE(J6),ENGLISH!B:B,0)),"")) -> 0 | I12: =IFERROR(INDEX(ENGLISH!L:L,MATCH(VALUE(J6),ENGLISH!B:B,0)),"") | J12: =IFERROR(INDEX(ENGLISH!M:M,MATCH(VALUE(J6),ENGLISH!B:B,0)),"") | K12: =IFERROR(INDEX(ENGLISH!O:O,MATCH(VALUE(J6),ENGLISH!B:B,0)),"") | L12: =IFERROR(INDEX(ENGLISH!P:P,MATCH(VALUE(J6),ENGLISH!B:B,0)),"")
B13: =IF(MATHEMATICS!D7="","",MATHEMATICS!D7) -> MATHEMATICS | C13: =IF(J7="","",IFERROR(INDEX(MATHEMATICS!E:E,MATCH(VALUE(J6),MATHEMATICS!B:B,0)),"")) -> 0 | D13: =IF(J7="","",IFERROR(INDEX(MATHEMATICS!F:F,MATCH(VALUE(J6),MATHEMATICS!B:B,0)),"")) -> 0 | E13: =IF(J7="","",IFERROR(INDEX(MATHEMATICS!G:G,MATCH(VALUE(J6),MATHEMATICS!B:B,0)),"")) -> 0 | F13: =IF(J7="","",IFERROR(INDEX(MATHEMATICS!H:H,MATCH(VALUE(J6),MATHEMATICS!B:B,0)),"")) -> 0 | G13: =IFERROR(INDEX(MATHEMATICS!J:J,MATCH(VALUE(J6),MATHEMATICS!B:B,0)),"") | H13: =IF(J7="","",IFERROR(INDEX(MATHEMATICS!K:K,MATCH(VALUE(J6),MATHEMATICS!B:B,0)),"")) -> 0 | I13: =IFERROR(INDEX(MATHEMATICS!L:L,MATCH(VALUE(J6),MATHEMATICS!B:B,0)),"") | J13: =IFERROR(INDEX(MATHEMATICS!M:M,MATCH(VALUE(J6),MATHEMATICS!B:B,0)),"") | K13: =IFERROR(INDEX(MATHEMATICS!O:O,MATCH(VALUE(J6),MATHEMATICS!B:B,0)),"") | L13: =IFERROR(INDEX(MATHEMATICS!P:P,MATCH(VALUE(J6),MATHEMATICS!B:B,0)),"")
B14: =IF(SCIENCE!D7="","",SCIENCE!D7) -> SCIENCE | C14: =IF(J7="","",IFERROR(INDEX(SCIENCE!E:E,MATCH(VALUE(J6),SCIENCE!B:B,0)),"")) -> 0 | D14: =IF(J7="","",IFERROR(INDEX(SCIENCE!F:F,MATCH(VALUE(J6),SCIENCE!B:B,0)),"")) -> 0 | E14: =IF(J7="","",IFERROR(INDEX(SCIENCE!G:G,MATCH(VALUE(J6),SCIENCE!B:B,0)),"")) -> 0 | F14: =IF(J7="","",IFERROR(INDEX(SCIENCE!H:H,MATCH(VALUE(J6),SCIENCE!B:B,0)),"")) -> 0 | G14: =IFERROR(INDEX(SCIENCE!J:J,MATCH(VALUE(J6),SCIENCE!B:B,0)),"") | H14: =IF(J7="","",IFERROR(INDEX(SCIENCE!K:K,MATCH(VALUE(J6),SCIENCE!B:B,0)),"")) -> 0 | I14: =IFERROR(INDEX(SCIENCE!L:L,MATCH(VALUE(J6),SCIENCE!B:B,0)),"") | J14: =IFERROR(INDEX(SCIENCE!M:M,MATCH(VALUE(J6),SCIENCE!B:B,0)),"") | K14: =IFERROR(INDEX(SCIENCE!O:O,MATCH(VALUE(J6),SCIENCE!B:B,0)),"") | L14: =IFERROR(INDEX(SCIENCE!P:P,MATCH(VALUE(J6),SCIENCE!B:B,0)),"")
B15: =IF(SOCIAL!D7="","",SOCIAL!D7) -> SOCIAL STUDIES | C15: =IF(J7="","",IFERROR(INDEX(SOCIAL!E:E,MATCH(VALUE(J6),SOCIAL!B:B,0)),"")) -> 0 | D15: =IF(J7="","",IFERROR(INDEX(SOCIAL!F:F,MATCH(VALUE(J6),SOCIAL!B:B,0)),"")) -> 0 | E15: =IF(J7="","",IFERROR(INDEX(SOCIAL!G:G,MATCH(VALUE(J6),SOCIAL!B:B,0)),"")) -> 0 | F15: =IF(J7="","",IFERROR(INDEX(SOCIAL!H:H,MATCH(VALUE(J6),SOCIAL!B:B,0)),"")) -> 0 | G15: =IFERROR(INDEX(SOCIAL!J:J,MATCH(VALUE(J6),SOCIAL!B:B,0)),"") | H15: =IF(J7="","",IFERROR(INDEX(SOCIAL!K:K,MATCH(VALUE(J6),SOCIAL!B:B,0)),"")) -> 0 | I15: =IFERROR(INDEX(SOCIAL!L:L,MATCH(VALUE(J6),SOCIAL!B:B,0)),"") | J15: =IFERROR(INDEX(SOCIAL!M:M,MATCH(VALUE(J6),SOCIAL!B:B,0)),"") | K15: =IFERROR(INDEX(SOCIAL!O:O,MATCH(VALUE(J6),SOCIAL!B:B,0)),"") | L15: =IFERROR(INDEX(SOCIAL!P:P,MATCH(VALUE(J6),SOCIAL!B:B,0)),"")
B16: =IF(COMPUTING!D7="","",COMPUTING!D7) -> COMPUTING | C16: =IF(J7="","",IFERROR(INDEX(COMPUTING!E:E,MATCH(VALUE(J6),COMPUTING!B:B,0)),"")) -> 0 | D16: =IF(J7="","",IFERROR(INDEX(COMPUTING!F:F,MATCH(VALUE(J6),COMPUTING!B:B,0)),"")) -> 0 | E16: =IF(J7="","",IFERROR(INDEX(COMPUTING!G:G,MATCH(VALUE(J6),COMPUTING!B:B,0)),"")) -> 0 | F16: =IF(J7="","",IFERROR(INDEX(COMPUTING!H:H,MATCH(VALUE(J6),COMPUTING!B:B,0)),"")) -> 0 | G16: =IFERROR(INDEX(COMPUTING!J:J,MATCH(VALUE(J6),COMPUTING!B:B,0)),"") | H16: =IF(J7="","",IFERROR(INDEX(COMPUTING!K:K,MATCH(VALUE(J6),COMPUTING!B:B,0)),"")) -> 0 | I16: =IFERROR(INDEX(COMPUTING!L:L,MATCH(VALUE(J6),COMPUTING!B:B,0)),"") | J16: =IFERROR(INDEX(COMPUTING!M:M,MATCH(VALUE(J6),COMPUTING!B:B,0)),"") | K16: =IFERROR(INDEX(COMPUTING!O:O,MATCH(VALUE(J6),COMPUTING!B:B,0)),"") | L16: =IFERROR(INDEX(COMPUTING!P:P,MATCH(VALUE(J6),COMPUTING!B:B,0)),"")
B17: =IF(RME!D7="","",RME!D7) -> RME | C17: =IF(J7="","",IFERROR(INDEX(RME!E:E,MATCH(VALUE(J6),RME!B:B,0)),"")) -> 0 | D17: =IF(J7="","",IFERROR(INDEX(RME!F:F,MATCH(VALUE(J6),RME!B:B,0)),"")) -> 0 | E17: =IF(J7="","",IFERROR(INDEX(RME!G:G,MATCH(VALUE(J6),RME!B:B,0)),"")) -> 0 | F17: =IF(J7="","",IFERROR(INDEX(RME!H:H,MATCH(VALUE(J6),RME!B:B,0)),"")) -> 0 | G17: =IFERROR(INDEX(RME!J:J,MATCH(VALUE(J6),RME!B:B,0)),"") | H17: =IF(J7="","",IFERROR(INDEX(RME!K:K,MATCH(VALUE(J6),RME!B:B,0)),"")) -> 0 | I17: =IFERROR(INDEX(RME!L:L,MATCH(VALUE(J6),RME!B:B,0)),"") | J17: =IFERROR(INDEX(RME!M:M,MATCH(VALUE(J6),RME!B:B,0)),"") | K17: =IFERROR(INDEX(RME!O:O,MATCH(VALUE(J6),RME!B:B,0)),"") | L17: =IFERROR(INDEX(RME!P:P,MATCH(VALUE(J6),RME!B:B,0)),"")
B18: =IF(CARRIERTECH!D7="","",CARRIERTECH!D7) -> CARRIER TECHNOLOGY | C18: =IF(J7="","",IFERROR(INDEX(CARRIERTECH!E:E,MATCH(VALUE(J6),CARRIERTECH!B:B,0)),"")) -> 0 | D18: =IF(J7="","",IFERROR(INDEX(CARRIERTECH!F:F,MATCH(VALUE(J6),CARRIERTECH!B:B,0)),"")) -> 0 | E18: =IF(J7="","",IFERROR(INDEX(CARRIERTECH!G:G,MATCH(VALUE(J6),CARRIERTECH!B:B,0)),"")) -> 0 | F18: =IF(J7="","",IFERROR(INDEX(CARRIERTECH!H:H,MATCH(VALUE(J6),CARRIERTECH!B:B,0)),"")) -> 0 | G18: =IFERROR(INDEX(CARRIERTECH!J:J,MATCH(VALUE(J6),CARRIERTECH!B:B,0)),"") | H18: =IF(J7="","",IFERROR(INDEX(CARRIERTECH!K:K,MATCH(VALUE(J6),CARRIERTECH!B:B,0)),"")) -> 0 | I18: =IFERROR(INDEX(CARRIERTECH!L:L,MATCH(VALUE(J6),CARRIERTECH!B:B,0)),"") | J18: =IFERROR(INDEX(CARRIERTECH!M:M,MATCH(VALUE(J6),CARRIERTECH!B:B,0)),"") | K18: =IFERROR(INDEX(CARRIERTECH!O:O,MATCH(VALUE(J6),CARRIERTECH!B:B,0)),"") | L18: =IFERROR(INDEX(CARRIERTECH!P:P,MATCH(VALUE(J6),CARRIERTECH!B:B,0)),"")
B19: =IF(CREATIVEART!D7="","",CREATIVEART!D7) -> CREATIVE ART | C19: =IF(J7="","",IFERROR(INDEX(CREATIVEART!E:E,MATCH(VALUE(J6),CREATIVEART!B:B,0)),"")) -> 0 | D19: =IF(J7="","",IFERROR(INDEX(CREATIVEART!F:F,MATCH(VALUE(J6),CREATIVEART!B:B,0)),"")) -> 0 | E19: =IF(J7="","",IFERROR(INDEX(CREATIVEART!G:G,MATCH(VALUE(J6),CREATIVEART!B:B,0)),"")) -> 0 | F19: =IF(J7="","",IFERROR(INDEX(CREATIVEART!H:H,MATCH(VALUE(J6),CREATIVEART!B:B,0)),"")) -> 0 | G19: =IFERROR(INDEX(CREATIVEART!J:J,MATCH(VALUE(J6),CREATIVEART!B:B,0)),"") | H19: =IF(J7="","",IFERROR(INDEX(CREATIVEART!K:K,MATCH(VALUE(J6),CREATIVEART!B:B,0)),"")) -> 0 | I19: =IFERROR(INDEX(CREATIVEART!L:L,MATCH(VALUE(J6),CREATIVEART!B:B,0)),"") | J19: =IFERROR(INDEX(CREATIVEART!M:M,MATCH(VALUE(J6),CREATIVEART!B:B,0)),"") | K19: =IFERROR(INDEX(CREATIVEART!O:O,MATCH(VALUE(J6),CREATIVEART!B:B,0)),"") | L19: =IFERROR(INDEX(CREATIVEART!P:P,MATCH(VALUE(J6),CREATIVEART!B:B,0)),"")
B20: =IF(GHLANGUAGE!D7="","",GHLANGUAGE!D7) -> GHANAIAN LANGUAGE | C20: =IF(J7="","",IFERROR(INDEX(GHLANGUAGE!E:E,MATCH(VALUE(J6),GHLANGUAGE!B:B,0)),"")) -> 0 | D20: =IF(J7="","",IFERROR(INDEX(GHLANGUAGE!F:F,MATCH(VALUE(J6),GHLANGUAGE!B:B,0)),"")) -> 0 | E20: =IF(J7="","",IFERROR(INDEX(GHLANGUAGE!G:G,MATCH(VALUE(J6),GHLANGUAGE!B:B,0)),"")) -> 0 | F20: =IF(J7="","",IFERROR(INDEX(GHLANGUAGE!H:H,MATCH(VALUE(J6),GHLANGUAGE!B:B,0)),"")) -> 0 | G20: =IFERROR(INDEX(GHLANGUAGE!J:J,MATCH(VALUE(J6),GHLANGUAGE!B:B,0)),"") | H20: =IF(J7="","",IFERROR(INDEX(GHLANGUAGE!K:K,MATCH(VALUE(J6),GHLANGUAGE!B:B,0)),"")) -> 0 | I20: =IFERROR(INDEX(GHLANGUAGE!L:L,MATCH(VALUE(J6),GHLANGUAGE!B:B,0)),"") | J20: =IFERROR(INDEX(GHLANGUAGE!M:M,MATCH(VALUE(J6),GHLANGUAGE!B:B,0)),"") | K20: =IFERROR(INDEX(GHLANGUAGE!O:O,MATCH(VALUE(J6),GHLANGUAGE!B:B,0)),"") | L20: =IFERROR(INDEX(GHLANGUAGE!P:P,MATCH(VALUE(J6),GHLANGUAGE!B:B,0)),"")
B21: REMARKS
B22: OVERALL AVERAGE: | C22: =IF(J7="","",AVERAGE(J12:J20)) -> #DIV/0!
B23: OVERALL GRADE: | C23: =IF(J7="","", IF(SUM(J12:J20)<=351,"F9",IF(SUM(J12:J20)<=396,"E8",IF(SUM(J12:J20)<=441,"D7",IF(SUM(J12:J20)<=486,"C6",IF(SUM(J12:J20)<=531,"C5",IF(SUM(J12:J20)<=576,"C4",IF(SUM(J12:J20)<=621,"B3",IF(SUM(J12:J20)<=711,"B2",IF(SUM(J12:J20)<=900,"A1")))))))))) -> F9
B24: OVERALL REMARKS: | C24: =IF(J7="","", IF( SUM(J12:J20)<=351,"Lowest",IF(SUM(J12:J20)<=396,"Lower",IF(SUM(J12:J20)<=441,"Low",IF(SUM(J12:J20)<=486,"Pass",IF(SUM(J12:J20)<=531,"Pass",IF(SUM(J12:J20)<=576,"Fair",IF(SUM(J12:J20)<=621,"Good!",IF(SUM(J12:J20)<=711,"Very Good!",IF(SUM(J12:J20)<=900,"Excellent!")))))))))) -> Lowest
B25: CLASS TEACHER'S COMMENT: | C25: =IF(J7="","", IF( SUM(J12:J20)<=351,"Performance Was Significantly Below Expectation, Revisit Materials And Seek Support To Improve",IF( SUM(J12:J20)<=486,"You've Not Meet The Required Standard, Focus on Key Concept To Do Better Next Time",IF(SUM(J12:J20)<=576,"Good Effort! You've Meet Minimum Requirement, Focus on Key Areas For Better Performance",IF(SUM(J12:J20)<=621,"Good! You've a Good Understanding, Still Need Improvement",IF(SUM(J12:J20)<=711,"Good Effort! You've a Strong Understanding, Still Need Improvement",IF(SUM(J12:J20)<=900,"You've Achieved an Outstanding Grades. Keep It Up!"))))))) -> Performance Was Significantly Below Expectation, Revisit Materials And Seek Support To Improve
B26: HEADMASTER'S COMMENT: | C26: =IF(J7="","", IF( SUM(J12:J20)<=351,"Significantly Below Expectation, Needs Extra Attention And Support To Improve",IF( SUM(J12:J20)<=486,"Not Meeting The Required Standard,Take serious The Key Concept To Do Better Next Time",IF(SUM(J12:J20)<=576,"Good Effort! You've Meet Minimum Requirement, Focus on Key Areas For Better Performance",IF(SUM(J12:J20)<=621,"Great! You've a Good Understanding, You Still Do Better",IF(SUM(J12:J20)<=711,"Very Good Effort! You've a Strong Understanding, You Can Still Do Better Than That",IF(SUM(J12:J20)<=900,"You've Excellent Achievement!, An Outstanding Grades. Keep It Up!"))))))) -> Significantly Below Expectation, Needs Extra Attention And Support To Improve
B27: CLASS TEACHER'S SIGNATURE | E27: HEADMASTER'S SIGNATURE | I27: PARENT'S SIGNATURE
I30: DEV. FEKPE JOHN +233241224773
B32: =SUMMARY!B2 -> jokpe School complex
C34: Student Report Card
C35: 2026
B36: NAME OF STUDENT: | C36: =IFERROR(INDEX(ENGLISH!C:C,MATCH(VALUE(J36),ENGLISH!B:B,0)),"") -> AMA JULIAM | G36: ADMISSION NUMBER: | J36: 2
B37: CLASS: | C37: =SUMMARY!B5 -> Basic 6 | G37: GENDER: | J37: =IFERROR(INDEX(ENGLISH!D:D,MATCH(VALUE(J6),ENGLISH!B:B,0)),"") -> M
B38: TERM: | C38: =SUMMARY!C4 -> First Term | G38: DATE: | J38: =DATAENTRY!K9 -> 44275
C40: Continuous Assessement A 100% | G40: Test A 50% | H40: Exam B 100% | I40: Exam B 50% | J40: Total (A+B) 100% | K40: Grade | L40: Remarks
B41: SUBJECTS | C41: Test1 | D41: Test2 | E41: Test3 | F41: Test4
B42: =IF(ENGLISH!D7="","",ENGLISH!D7) -> ENGLISH LANGUAGE | C42: =IF(J37="","", IFERROR(INDEX(ENGLISH!E:E,MATCH(VALUE(J36),ENGLISH!B:B,0)),"")) -> 0 | D42: =IF(J37="","",IFERROR(INDEX(ENGLISH!F:F,MATCH(VALUE(J36),ENGLISH!B:B,0)),"")) -> 0 | E42: =IF(J37="","",IFERROR(INDEX(ENGLISH!G:G,MATCH(VALUE(J36),ENGLISH!B:B,0)),"")) -> 0 | F42: =IF(J37="","",IFERROR(INDEX(ENGLISH!H:H,MATCH(VALUE(J36),ENGLISH!B:B,0)),"")) -> 0 | G42: =IFERROR(INDEX(ENGLISH!J:J,MATCH(VALUE(J36),ENGLISH!B:B,0)),"") | H42: =IF(J37="","",IFERROR(INDEX(ENGLISH!K:K,MATCH(VALUE(J36),ENGLISH!B:B,0)),"")) -> 0 | I42: =IFERROR(INDEX(ENGLISH!L:L,MATCH(VALUE(J36),ENGLISH!B:B,0)),"") | J42: =IFERROR(INDEX(ENGLISH!M:M,MATCH(VALUE(J36),ENGLISH!B:B,0)),"") | K42: =IFERROR(INDEX(ENGLISH!O:O,MATCH(VALUE(J36),ENGLISH!B:B,0)),"") | L42: =IFERROR(INDEX(ENGLISH!P:P,MATCH(VALUE(J36),ENGLISH!B:B,0)),"")
B43: =IF(MATHEMATICS!D7="","",MATHEMATICS!D7) -> MATHEMATICS | C43: =IF(J37="","",IFERROR(INDEX(MATHEMATICS!E:E,MATCH(VALUE(J36),MATHEMATICS!B:B,0)),"")) -> 0 | D43: =IF(J37="","",IFERROR(INDEX(MATHEMATICS!F:F,MATCH(VALUE(J36),MATHEMATICS!B:B,0)),"")) -> 0 | E43: =IF(J37="","",IFERROR(INDEX(MATHEMATICS!G:G,MATCH(VALUE(J36),MATHEMATICS!B:B,0)),"")) -> 0 | F43: =IF(J37="","",IFERROR(INDEX(MATHEMATICS!H:H,MATCH(VALUE(J36),MATHEMATICS!B:B,0)),"")) -> 0 | G43: =IFERROR(INDEX(MATHEMATICS!J:J,MATCH(VALUE(J36),MATHEMATICS!B:B,0)),"") | H43: =IF(J37="","",IFERROR(INDEX(MATHEMATICS!K:K,MATCH(VALUE(J36),MATHEMATICS!B:B,0)),"")) -> 0 | I43: =IFERROR(INDEX(MATHEMATICS!L:L,MATCH(VALUE(J36),MATHEMATICS!B:B,0)),"") | J43: =IFERROR(INDEX(MATHEMATICS!M:M,MATCH(VALUE(J36),MATHEMATICS!B:B,0)),"") | K43: =IFERROR(INDEX(MATHEMATICS!O:O,MATCH(VALUE(J36),MATHEMATICS!B:B,0)),"") | L43: =IFERROR(INDEX(MATHEMATICS!P:P,MATCH(VALUE(J36),MATHEMATICS!B:B,0)),"")
B44: =IF(SCIENCE!D7="","",SCIENCE!D7) -> SCIENCE | C44: =IF(J37="","",IFERROR(INDEX(SCIENCE!E:E,MATCH(VALUE(J36),SCIENCE!B:B,0)),"")) -> 0 | D44: =IF(J37="","",IFERROR(INDEX(SCIENCE!F:F,MATCH(VALUE(J36),SCIENCE!B:B,0)),"")) -> 0 | E44: =IF(J37="","",IFERROR(INDEX(SCIENCE!G:G,MATCH(VALUE(J36),SCIENCE!B:B,0)),"")) -> 0 | F44: =IF(J37="","",IFERROR(INDEX(SCIENCE!H:H,MATCH(VALUE(J36),SCIENCE!B:B,0)),"")) -> 0 | G44: =IFERROR(INDEX(SCIENCE!J:J,MATCH(VALUE(J36),SCIENCE!B:B,0)),"") | H44: =IF(J37="","",IFERROR(INDEX(SCIENCE!K:K,MATCH(VALUE(J36),SCIENCE!B:B,0)),"")) -> 0 | I44: =IFERROR(INDEX(SCIENCE!L:L,MATCH(VALUE(J36),SCIENCE!B:B,0)),"") | J44: =IFERROR(INDEX(SCIENCE!M:M,MATCH(VALUE(J36),SCIENCE!B:B,0)),"") | K44: =IFERROR(INDEX(SCIENCE!O:O,MATCH(VALUE(J36),SCIENCE!B:B,0)),"") | L44: =IFERROR(INDEX(SCIENCE!P:P,MATCH(VALUE(J36),SCIENCE!B:B,0)),"")
B45: =IF(SOCIAL!D7="","",SOCIAL!D7) -> SOCIAL STUDIES | C45: =IF(J37="","",IFERROR(INDEX(SOCIAL!E:E,MATCH(VALUE(J36),SOCIAL!B:B,0)),"")) -> 0 | D45: =IF(J37="","",IFERROR(INDEX(SOCIAL!F:F,MATCH(VALUE(J36),SOCIAL!B:B,0)),"")) -> 0 | E45: =IF(J37="","",IFERROR(INDEX(SOCIAL!G:G,MATCH(VALUE(J36),SOCIAL!B:B,0)),"")) -> 0 | F45: =IF(J37="","",IFERROR(INDEX(SOCIAL!H:H,MATCH(VALUE(J36),SOCIAL!B:B,0)),"")) -> 0 | G45: =IFERROR(INDEX(SOCIAL!J:J,MATCH(VALUE(J36),SOCIAL!B:B,0)),"") | H45: =IF(J37="","",IFERROR(INDEX(SOCIAL!K:K,MATCH(VALUE(J36),SOCIAL!B:B,0)),"")) -> 0 | I45: =IFERROR(INDEX(SOCIAL!L:L,MATCH(VALUE(J36),SOCIAL!B:B,0)),"") | J45: =IFERROR(INDEX(SOCIAL!M:M,MATCH(VALUE(J36),SOCIAL!B:B,0)),"") | K45: =IFERROR(INDEX(SOCIAL!O:O,MATCH(VALUE(J36),SOCIAL!B:B,0)),"") | L45: =IFERROR(INDEX(SOCIAL!P:P,MATCH(VALUE(J36),SOCIAL!B:B,0)),"")
B46: =IF(COMPUTING!D7="","",COMPUTING!D7) -> COMPUTING | C46: =IF(J37="","",IFERROR(INDEX(COMPUTING!E:E,MATCH(VALUE(J36),COMPUTING!B:B,0)),"")) -> 0 | D46: =IF(J37="","",IFERROR(INDEX(COMPUTING!F:F,MATCH(VALUE(J36),COMPUTING!B:B,0)),"")) -> 0 | E46: =IF(J37="","",IFERROR(INDEX(COMPUTING!G:G,MATCH(VALUE(J36),COMPUTING!B:B,0)),"")) -> 0 | F46: =IF(J37="","",IFERROR(INDEX(COMPUTING!H:H,MATCH(VALUE(J36),COMPUTING!B:B,0)),"")) -> 0 | G46: =IFERROR(INDEX(COMPUTING!J:J,MATCH(VALUE(J36),COMPUTING!B:B,0)),"") | H46: =IF(J37="","",IFERROR(INDEX(COMPUTING!K:K,MATCH(VALUE(J36),COMPUTING!B:B,0)),"")) -> 0 | I46: =IFERROR(INDEX(COMPUTING!L:L,MATCH(VALUE(J36),COMPUTING!B:B,0)),"") | J46: =IFERROR(INDEX(COMPUTING!M:M,MATCH(VALUE(J36),COMPUTING!B:B,0)),"") | K46: =IFERROR(INDEX(COMPUTING!O:O,MATCH(VALUE(J36),COMPUTING!B:B,0)),"") | L46: =IFERROR(INDEX(COMPUTING!P:P,MATCH(VALUE(J36),COMPUTING!B:B,0)),"")
B47: =IF(RME!D7="","",RME!D7) -> RME | C47: =IF(J37="","",IFERROR(INDEX(RME!E:E,MATCH(VALUE(J36),RME!B:B,0)),"")) -> 0 | D47: =IF(J37="","",IFERROR(INDEX(RME!F:F,MATCH(VALUE(J36),RME!B:B,0)),"")) -> 0 | E47: =IF(J37="","",IFERROR(INDEX(RME!G:G,MATCH(VALUE(J36),RME!B:B,0)),"")) -> 0 | F47: =IF(J37="","",IFERROR(INDEX(RME!H:H,MATCH(VALUE(J36),RME!B:B,0)),"")) -> 0 | G47: =IFERROR(INDEX(RME!J:J,MATCH(VALUE(J36),RME!B:B,0)),"") | H47: =IF(J37="","",IFERROR(INDEX(RME!K:K,MATCH(VALUE(J36),RME!B:B,0)),"")) -> 0 | I47: =IFERROR(INDEX(RME!L:L,MATCH(VALUE(J36),RME!B:B,0)),"") | J47: =IFERROR(INDEX(RME!M:M,MATCH(VALUE(J36),RME!B:B,0)),"") | K47: =IFERROR(INDEX(RME!O:O,MATCH(VALUE(J36),RME!B:B,0)),"") | L47: =IFERROR(INDEX(RME!P:P,MATCH(VALUE(J36),RME!B:B,0)),"")
B48: =IF(CARRIERTECH!D7="","",CARRIERTECH!D7) -> CARRIER TECHNOLOGY | C48: =IF(J37="","",IFERROR(INDEX(CARRIERTECH!E:E,MATCH(VALUE(J36),CARRIERTECH!B:B,0)),"")) -> 0 | D48: =IF(J37="","",IFERROR(INDEX(CARRIERTECH!F:F,MATCH(VALUE(J36),CARRIERTECH!B:B,0)),"")) -> 0 | E48: =IF(J37="","",IFERROR(INDEX(CARRIERTECH!G:G,MATCH(VALUE(J36),CARRIERTECH!B:B,0)),"")) -> 0 | F48: =IF(J37="","",IFERROR(INDEX(CARRIERTECH!H:H,MATCH(VALUE(J36),CARRIERTECH!B:B,0)),"")) -> 0 | G48: =IFERROR(INDEX(CARRIERTECH!J:J,MATCH(VALUE(J36),CARRIERTECH!B:B,0)),"") | H48: =IF(J37="","",IFERROR(INDEX(CARRIERTECH!K:K,MATCH(VALUE(J36),CARRIERTECH!B:B,0)),"")) -> 0 | I48: =IFERROR(INDEX(CARRIERTECH!L:L,MATCH(VALUE(J36),CARRIERTECH!B:B,0)),"") | J48: =IFERROR(INDEX(CARRIERTECH!M:M,MATCH(VALUE(J36),CARRIERTECH!B:B,0)),"") | K48: =IFERROR(INDEX(CARRIERTECH!O:O,MATCH(VALUE(J36),CARRIERTECH!B:B,0)),"") | L48: =IFERROR(INDEX(CARRIERTECH!P:P,MATCH(VALUE(J36),CARRIERTECH!B:B,0)),"")
...

Sheet ENGLISH
B3: =DATAENTRY!B2 -> jokpe School complex
C5: =DATAENTRY!C4 -> First Term
C6: =DATAENTRY!D5 -> Basic 6
C7: TERM ENDING | D7: ENGLISH LANGUAGE | I7: MALE: | J7: =COUNTIF(D10:D54,"=M") -> 3 | K7: FEMALE: | M7: =COUNTIF(D10:D54,"=F") -> 3 | N7: TOTAL: | O7: =SUM(J7+M7) -> 6
B8: S/N | C8: =DATAENTRY!D9 -> 0 | D8: =DATAENTRY!G9 -> First Term | G8: CLASS ASSESSMENT SCORE | M8: Dev's. Contact: Fekpe John: +233241224773
C9: NAME OF STUDENT | D9: SEX | E9: TEST 1 15MK | F9: TEST2 15MK | G9: TEST3 15MK | H9: PROJ. 15MK | I9: TOTAL (A) | J9: 50% (A) | K9: EXAM 100 | L9: 50% (B) | M9: TOTAL (A+B) | N9: POSITIONS | O9: GRADE | P9: REMARK
B10: 1 | C10: =IF(DATAENTRY!C12="","",DATAENTRY!C12) -> KOFI AKPALU | D10: =IF(DATAENTRY!D12="","",DATAENTRY!D12) -> M | I10: =IF(H10="","",SUM(E10:H10)) | J10: =IF(I10="","",I10*5/6) | L10: =IF(K10="","",K10*0.5) | M10: =IF(J10="","",J10+L10) | N10: =IF(M10="","",RANK(M10,$M$10:$M$54,FALSE)) | O10: =IF(M10="","",IF(M10<=39,"F9",IF(M10<=44,"E8",IF(M10<=49,"D7",IF(M10<=54,"C6",IF(M10<=59,"C5",IF(M10<=64,"C4",IF(M10<=69,"B3",IF(M10<=79,"B2",IF(M10<=100,"A1")))))))))) | P10: =IF(M10="","",IF(M10<=39,"Fail",IF(M10<=44,"Pass",IF(M10<=49,"Pass",IF(M10<=54,"Credit",IF(M10<=59,"Credit",IF(M10<=64,"Credit",IF(M10<=69,"Good",IF(M10<=79,"Very Good",IF(M10<=100,"Excellent"))))))))))
B11: 2 | C11: =IF(DATAENTRY!C13="","",DATAENTRY!C13) -> AMA JULIAM | D11: =IF(DATAENTRY!D13="","",DATAENTRY!D13) -> F | I11: =IF(H11="","",SUM(E11:H11)) | J11: =IF(I11="","",I11*5/6) | L11: =IF(K11="","",K11*0.5) | M11: =IF(J11="","",J11+L11) | N11: =IF(M11="","",RANK(M11,$M$10:$M$54,FALSE)) | O11: =IF(M11="","",IF(M11<=39,"F9",IF(M11<=44,"E8",IF(M11<=49,"D7",IF(M11<=54,"C6",IF(M11<=59,"C5",IF(M11<=64,"C4",IF(M11<=69,"B3",IF(M11<=79,"B2",IF(M11<=100,"A1")))))))))) | P11: =IF(M11="","",IF(M11<=39,"Fail",IF(M11<=44,"Pass",IF(M11<=49,"Pass",IF(M11<=54,"Credit",IF(M11<=59,"Credit",IF(M11<=64,"Credit",IF(M11<=69,"Good",IF(M11<=79,"Very Good",IF(M11<=100,"Excellent"))))))))))
B12: 3 | C12: =IF(DATAENTRY!C14="","",DATAENTRY!C14) -> KOKU BONTO | D12: =IF(DATAENTRY!D14="","",DATAENTRY!D14) -> M | I12: =IF(H12="","",SUM(E12:H12)) | J12: =IF(I12="","",I12*5/6) | L12: =IF(K12="","",K12*0.5) | M12: =IF(J12="","",J12+L12) | N12: =IF(M12="","",RANK(M12,$M$10:$M$54,FALSE)) | O12: =IF(M12="","",IF(M12<=39,"F9",IF(M12<=44,"E8",IF(M12<=49,"D7",IF(M12<=54,"C6",IF(M12<=59,"C5",IF(M12<=64,"C4",IF(M12<=69,"B3",IF(M12<=79,"B2",IF(M12<=100,"A1")))))))))) | P12: =IF(M12="","",IF(M12<=39,"Fail",IF(M12<=44,"Pass",IF(M12<=49,"Pass",IF(M12<=54,"Credit",IF(M12<=59,"Credit",IF(M12<=64,"Credit",IF(M12<=69,"Good",IF(M12<=79,"Very Good",IF(M12<=100,"Excellent"))))))))))
B13: 4 | C13: =IF(DATAENTRY!C15="","",DATAENTRY!C15) -> DODOUKWE CHABA | D13: =IF(DATAENTRY!D15="","",DATAENTRY!D15) -> F | I13: =IF(H13="","",SUM(E13:H13)) | J13: =IF(I13="","",I13*5/6) | L13: =IF(K13="","",K13*0.5) | M13: =IF(J13="","",J13+L13) | N13: =IF(M13="","",RANK(M13,$M$10:$M$54,FALSE)) | O13: =IF(M13="","",IF(M13<=39,"F9",IF(M13<=44,"E8",IF(M13<=49,"D7",IF(M13<=54,"C6",IF(M13<=59,"C5",IF(M13<=64,"C4",IF(M13<=69,"B3",IF(M13<=79,"B2",IF(M13<=100,"A1")))))))))) | P13: =IF(M13="","",IF(M13<=39,"Fail",IF(M13<=44,"Pass",IF(M13<=49,"Pass",IF(M13<=54,"Credit",IF(M13<=59,"Credit",IF(M13<=64,"Credit",IF(M13<=69,"Good",IF(M13<=79,"Very Good",IF(M13<=100,"Excellent"))))))))))
B14: 5 | C14: =IF(DATAENTRY!C16="","",DATAENTRY!C16) -> AMINA FRIDAY | D14: =IF(DATAENTRY!D16="","",DATAENTRY!D16) -> M | I14: =IF(H14="","",SUM(E14:H14)) | J14: =IF(I14="","",I14*5/6) | L14: =IF(K14="","",K14*0.5) | M14: =IF(J14="","",J14+L14) | N14: =IF(M14="","",RANK(M14,$M$10:$M$54,FALSE)) | O14: =IF(M14="","",IF(M14<=39,"F9",IF(M14<=44,"E8",IF(M14<=49,"D7",IF(M14<=54,"C6",IF(M14<=59,"C5",IF(M14<=64,"C4",IF(M14<=69,"B3",IF(M14<=79,"B2",IF(M14<=100,"A1")))))))))) | P14: =IF(M14="","",IF(M14<=39,"Fail",IF(M14<=44,"Pass",IF(M14<=49,"Pass",IF(M14<=54,"Credit",IF(M14<=59,"Credit",IF(M14<=64,"Credit",IF(M14<=69,"Good",IF(M14<=79,"Very Good",IF(M14<=100,"Excellent"))))))))))
